Workbook

Sheet Inputs
A1: AGnVET Services — IK Caldwell
A2: 2026 Fungicide Trials — Mixing Plan
A4: Parameter | B4: Value | C4: Unit | D4: Basis
A5: Plot width | B5: 2 | C5: m | D5: Trial spec
A6: Plot length | B6: 12 | C6: m | D6: Trial spec
A7: Plot area | B7: =B5*B6 -> 24 | C7: m² | D7: width × length
A8: Replicates | B8: 4 | C8: no. | D8: Trial spec
A9: Water rate | B9: 100 | C9: L/ha | D9: Trial spec
A10: Water required per plot | B10: =B7/10000*B9 -> 0.24 | C10: L | D10: plot area ÷ 10,000 × water rate
A11: Water required per treatment | B11: =B10*B8 -> 0.96 | C11: L | D11: per plot × replicates
A12: Overage per batch | B12: 0.54 | C12: L | D12: Priming / dead volume — adjust to suit sprayer
A13: BATCH VOLUME PER TREATMENT | B13: =B11+B12 -> 1.5 | C13: L | D13: required + overage. Drives every ml figure.
A15: Legend
A16: Yellow / blue cells are inputs — change these only. Everything else is a formula.
A17: Rates entered as ml/ha, g/ha or % v/v. Adjuvant % is v/v of the batch volume.
A18: Measure product with graduated syringes. Anything under 3 ml — make a 10× stock dilution and draw 10× the volume.
A19: Site agronomy, growth stages and layout: see the 2026 Fungicide Trials Site Information Sheet.

Sheet Barley Mixing
A1: AGnVET Services — IK Caldwell
A2: Barley Fungicide Trial — Matong — Mixing Plan
A3: Batch volume per treatment (L): | D3: =Inputs!B13 -> 1.5 | E3: Water per plot (L): | F3: =Inputs!B10 -> 0.24
A5: Trt | B5: Treatment | C5: Timing | D5: Product | E5: Rate | F5: Unit | G5: Per batch (ml) | H5: Check
A6: 1 | B6: Untreated | C6: A | D6: Water only
A7: 2 | B7: Aviator Xpro | C7: A | D7: Aviator Xpro | E7: 500 | F7: ml/ha | G7: =IF(F7="% v/v",$D$3*1000*E7/100,E7*$D$3/Inputs!$B$9) -> 7.5 | H7: x
A8: 3 | B8: Elatus Ace | C8: A | D8: Elatus Ace | E8: 500 | F8: ml/ha | G8: =IF(F8="% v/v",$D$3*1000*E8/100,E8*$D$3/Inputs!$B$9) -> 7.5 | H8: x
A9: 4 | B9: Proviso Plus Azx | C9: A | D9: Proviso Opti | E9: 240 | F9: ml/ha | G9: =IF(F9="% v/v",$D$3*1000*E9/100,E9*$D$3/Inputs!$B$9) -> 3.6 | H9: x
D10: Azoxystrobin | E10: 300 | F10: ml/ha | G10: =IF(F10="% v/v",$D$3*1000*E10/100,E10*$D$3/Inputs!$B$9) -> 4.5 | H10: x
D11: BS1000 | E11: 0.25 | F11: % v/v | G11: =IF(F11="% v/v",$D$3*1000*E11/100,E11*$D$3/Inputs!$B$9) -> 3.75 | H11: x
A12: 5 | B12: Proviso Opti | C12: A | D12: Proviso Opti | E12: 240 | F12: ml/ha | G12: =IF(F12="% v/v",$D$3*1000*E12/100,E12*$D$3/Inputs!$B$9) -> 3.6 | H12: x
D13: BS1000 | E13: 0.25 | F13: % v/v | G13: =IF(F13="% v/v",$D$3*1000*E13/100,E13*$D$3/Inputs!$B$9) -> 3.75 | H13: x
A14: 6 | B14: Revystar | C14: A | D14: Revystar | E14: 750 | F14: ml/ha | G14: =IF(F14="% v/v",$D$3*1000*E14/100,E14*$D$3/Inputs!$B$9) -> 11.25 | H14: x
A15: 7 | B15: Balaya | C15: A | D15: Balaya | E15: 750 | F15: ml/ha | G15: =IF(F15="% v/v",$D$3*1000*E15/100,E15*$D$3/Inputs!$B$9) -> 11.25 | H15: x
A16: 8 | B16: Elatus Flexi | C16: A | D16: Elatus Flexi | E16: 500 | F16: ml/ha | G16: =IF(F16="% v/v",$D$3*1000*E16/100,E16*$D$3/Inputs!$B$9) -> 7.5 | H16: x
D17: Proviso Opti | E17: 240 | F17: ml/ha | G17: =IF(F17="% v/v",$D$3*1000*E17/100,E17*$D$3/Inputs!$B$9) -> 3.6 | H17: x
D18: BS1000 | E18: 0.25 | F18: % v/v | G18: =IF(F18="% v/v",$D$3*1000*E18/100,E18*$D$3/Inputs!$B$9) -> 3.75 | H18: x
A19: 9 | B19: Experimental 2 AH | C19: A | D19: Vimoy Iblon (Bayer) | E19: 500 | F19: ml/ha | G19: =IF(F19="% v/v",$D$3*1000*E19/100,E19*$D$3/Inputs!$B$9) -> 7.5 | H19: x
D20: Proviso Opti | E20: 240 | F20: ml/ha | G20: =IF(F20="% v/v",$D$3*1000*E20/100,E20*$D$3/Inputs!$B$9) -> 3.6 | H20: x
D21: BS1000 | E21: 0.25 | F21: % v/v | G21: =IF(F21="% v/v",$D$3*1000*E21/100,E21*$D$3/Inputs!$B$9) -> 3.75 | H21: x
A22: 10 | B22: Experimental 3 A | C22: A | D22: Elatus Flexi | E22: 500 | F22: ml/ha | G22: =IF(F22="% v/v",$D$3*1000*E22/100,E22*$D$3/Inputs!$B$9) -> 7.5 | H22: x
A23: 11 | B23: Experimental 4 A | C23: A | D23: CUF37 (Syngenta) | E23: 750 | F23: ml/ha | G23: =IF(F23="% v/v",$D$3*1000*E23/100,E23*$D$3/Inputs!$B$9) -> 11.25 | H23: x
A24: 12 | B24: Balaya B | C24: A | D24: Proviso Opti | E24: 240 | F24: ml/ha | G24: =IF(F24="% v/v",$D$3*1000*E24/100,E24*$D$3/Inputs!$B$9) -> 3.6 | H24: x
D25: BS1000 | E25: 0.25 | F25: % v/v | G25: =IF(F25="% v/v",$D$3*1000*E25/100,E25*$D$3/Inputs!$B$9) -> 3.75 | H25: x
A26: 12 | B26: Balaya B | C26: B | D26: Balaya | E26: 750 | F26: ml/ha | G26: =IF(F26="% v/v",$D$3*1000*E26/100,E26*$D$3/Inputs!$B$9) -> 11.25 | H26: ☐
A27: 13 | B27: Experimental 2 BH | C27: A | D27: Proviso Opti | E27: 240 | F27: ml/ha | G27: =IF(F27="% v/v",$D$3*1000*E27/100,E27*$D$3/Inputs!$B$9) -> 3.6 | H27: x
D28: BS1000 | E28: 0.25 | F28: % v/v | G28: =IF(F28="% v/v",$D$3*1000*E28/100,E28*$D$3/Inputs!$B$9) -> 3.75 | H28: x
A29: 13 | B29: Experimental 2 BH | C29: B | D29: Vimoy Iblon (Bayer) | E29: 500 | F29: ml/ha | G29: =IF(F29="% v/v",$D$3*1000*E29/100,E29*$D$3/Inputs!$B$9) -> 7.5
D30: Proviso Opti | E30: 240 | F30: ml/ha | G30: =IF(F30="% v/v",$D$3*1000*E30/100,E30*$D$3/Inputs!$B$9) -> 3.6 | H30: ☐
D31: BS1000 | E31: 0.25 | F31: % v/v | G31: =IF(F31="% v/v",$D$3*1000*E31/100,E31*$D$3/Inputs!$B$9) -> 3.75 | H31: ☐
A32: 14 | B32: Experimental 3 B | C32: A | D32: Proviso Opti | E32: 240 | F32: ml/ha | G32: =IF(F32="% v/v",$D$3*1000*E32/100,E32*$D$3/Inputs!$B$9) -> 3.6 | H32: x
D33: BS1000 | E33: 0.25 | F33: % v/v | G33: =IF(F33="% v/v",$D$3*1000*E33/100,E33*$D$3/Inputs!$B$9) -> 3.75 | H33: x
A34: 14 | B34: Experimental 3 B | C34: B | D34: Elatus Flexi | E34: 500 | F34: ml/ha | G34: =IF(F34="% v/v",$D$3*1000*E34/100,E34*$D$3/Inputs!$B$9) -> 7.5 | H34: ☐
D35: Proviso Opti | E35: 240 | F35: ml/ha | G35: =IF(F35="% v/v",$D$3*1000*E35/100,E35*$D$3/Inputs!$B$9) -> 3.6 | H35: ☐
D36: BS1000 | E36: 0.25 | F36: % v/v | G36: =IF(F36="% v/v",$D$3*1000*E36/100,E36*$D$3/Inputs!$B$9) -> 3.75 | H36: ☐
A37: 15 | B37: Experimental 4 B | C37: A | D37: Proviso Opti | E37: 240 | F37: ml/ha | G37: =IF(F37="% v/v",$D$3*1000*E37/100,E37*$D$3/Inputs!$B$9) -> 3.6 | H37: x
D38: BS1000 | E38: 0.25 | F38: % v/v | G38: =IF(F38="% v/v",$D$3*1000*E38/100,E38*$D$3/Inputs!$B$9) -> 3.75 | H38: x
A39: 15 | B39: Experimental 4 B | C39: B | D39: CUF37 (Syngenta) | E39: 750 | F39: ml/ha | G39: =IF(F39="% v/v",$D$3*1000*E39/100,E39*$D$3/Inputs!$B$9) -> 11.25 | H39: ☐
A42: Total product required across all batches
A43: Product | B43: Total (ml)
...

Sheet Wheat Mixing
A1: AGnVET Services — IK Caldwell
A2: Wheat Fungicide Trial — Ringwood (Corowa) + Matong — Mixing Plan (rev. C, 24 treatments)
A3: Batch volume per treatment (L): | D3: =Inputs!B13 -> 1.5 | E3: Water per plot (L): | F3: =Inputs!B10 -> 0.24
A5: Trt | B5: Treatment | C5: Timing | D5: Product | E5: Rate | F5: Unit | G5: Per batch (ml) | H5: Check
A6: 1 | B6: Untreated | C6: A | D6: Water only
A7: 2 | B7: Aviator Xpro | C7: A | D7: Aviator Xpro | E7: 500 | F7: ml/ha | G7: =IF(F7="% v/v",$D$3*1000*E7/100,E7*$D$3/Inputs!$B$9) -> 7.5 | H7: x
A8: 3 | B8: Elatus Ace | C8: A | D8: Elatus Ace | E8: 500 | F8: ml/ha | G8: =IF(F8="% v/v",$D$3*1000*E8/100,E8*$D$3/Inputs!$B$9) -> 7.5 | H8: x
A9: 4 | B9: Opera | C9: A | D9: Opera | E9: 750 | F9: ml/ha | G9: =IF(F9="% v/v",$D$3*1000*E9/100,E9*$D$3/Inputs!$B$9) -> 11.25 | H9: x
A10: 5 | B10: Radial Opti (made up) | C10: A | D10: Amistar 250 SC | E10: 320 | F10: ml/ha | G10: =IF(F10="% v/v",$D$3*1000*E10/100,E10*$D$3/Inputs!$B$9) -> 4.8 | H10: x
D11: Soprano 500 | E11: 125 | F11: ml/ha | G11: =IF(F11="% v/v",$D$3*1000*E11/100,E11*$D$3/Inputs!$B$9) -> 1.875 | H11: x
D12: Hasten | E12: 0.5 | F12: % v/v | G12: =IF(F12="% v/v",$D$3*1000*E12/100,E12*$D$3/Inputs!$B$9) -> 7.5 | H12: x
A13: 6 | B13: Proviso Opti | C13: A | D13: Proline | E13: 240 | F13: ml/ha | G13: =IF(F13="% v/v",$D$3*1000*E13/100,E13*$D$3/Inputs!$B$9) -> 3.6 | H13: x
D14: BS1000 | E14: 0.25 | F14: % v/v | G14: =IF(F14="% v/v",$D$3*1000*E14/100,E14*$D$3/Inputs!$B$9) -> 3.75 | H14: x
A15: 7 | B15: Revystar | C15: A | D15: Revystar | E15: 750 | F15: ml/ha | G15: =IF(F15="% v/v",$D$3*1000*E15/100,E15*$D$3/Inputs!$B$9) -> 11.25 | H15: x
A16: 8 | B16: Balaya A+B | C16: A | D16: Balaya | E16: 750 | F16: ml/ha | G16: =IF(F16="% v/v",$D$3*1000*E16/100,E16*$D$3/Inputs!$B$9) -> 11.25 | H16: x
A17: 9 | B17: Flute A | C17: A | D17: Flute | E17: 150 | F17: ml/ha | G17: =IF(F17="% v/v",$D$3*1000*E17/100,E17*$D$3/Inputs!$B$9) -> 2.25 | H17: x
D18: Proviso Opti | E18: 240 | F18: ml/ha | G18: =IF(F18="% v/v",$D$3*1000*E18/100,E18*$D$3/Inputs!$B$9) -> 3.6 | H18: x
D19: BS1000 | E19: 0.25 | F19: % v/v | G19: =IF(F19="% v/v",$D$3*1000*E19/100,E19*$D$3/Inputs!$B$9) -> 3.75 | H19: x
A20: 10 | B20: Experimental 1 A | C20: A | D20: G295 (Adama) | E20: 150 | F20: ml/ha | G20: =IF(F20="% v/v",$D$3*1000*E20/100,E20*$D$3/Inputs!$B$9) -> 2.25 | H20: x
D21: Proviso Opti | E21: 240 | F21: ml/ha | G21: =IF(F21="% v/v",$D$3*1000*E21/100,E21*$D$3/Inputs!$B$9) -> 3.6 | H21: x
D22: BS1000 | E22: 0.25 | F22: % v/v | G22: =IF(F22="% v/v",$D$3*1000*E22/100,E22*$D$3/Inputs!$B$9) -> 3.75 | H22: x
A23: 11 | B23: Experimental 2 AL | C23: A | D23: Vimoy Iblon (Bayer) | E23: 300 | F23: ml/ha | G23: =IF(F23="% v/v",$D$3*1000*E23/100,E23*$D$3/Inputs!$B$9) -> 4.5 | H23: x
D24: Proviso Opti | E24: 240 | F24: ml/ha | G24: =IF(F24="% v/v",$D$3*1000*E24/100,E24*$D$3/Inputs!$B$9) -> 3.6 | H24: x
D25: BS1000 | E25: 0.25 | F25: % v/v | G25: =IF(F25="% v/v",$D$3*1000*E25/100,E25*$D$3/Inputs!$B$9) -> 3.75 | H25: x
A26: 12 | B26: Experimental 2 AH | C26: A | D26: Vimoy Iblon (Bayer) | E26: 500 | F26: ml/ha | G26: =IF(F26="% v/v",$D$3*1000*E26/100,E26*$D$3/Inputs!$B$9) -> 7.5 | H26: x
D27: Proviso Opti | E27: 240 | F27: ml/ha | G27: =IF(F27="% v/v",$D$3*1000*E27/100,E27*$D$3/Inputs!$B$9) -> 3.6 | H27: x
D28: BS1000 | E28: 0.25 | F28: % v/v | G28: =IF(F28="% v/v",$D$3*1000*E28/100,E28*$D$3/Inputs!$B$9) -> 3.75 | H28: x
A29: 13 | B29: Experimental 3 A | C29: A | D29: Elatus Flexi | E29: 500 | F29: ml/ha | G29: =IF(F29="% v/v",$D$3*1000*E29/100,E29*$D$3/Inputs!$B$9) -> 7.5 | H29: x
D30: Proviso Opti | E30: 240 | F30: ml/ha | G30: =IF(F30="% v/v",$D$3*1000*E30/100,E30*$D$3/Inputs!$B$9) -> 3.6 | H30: x
D31: BS1000 | E31: 0.25 | F31: % v/v | G31: =IF(F31="% v/v",$D$3*1000*E31/100,E31*$D$3/Inputs!$B$9) -> 3.75 | H31: x
A32: 14 | B32: Experimental 4 A | C32: A | D32: CUF37 (Syngenta) | E32: 750 | F32: ml/ha | G32: =IF(F32="% v/v",$D$3*1000*E32/100,E32*$D$3/Inputs!$B$9) -> 11.25 | H32: x
A33: 15 | B33: Balaya B | C33: A | D33: Soprano 500 | E33: 125 | F33: ml/ha | G33: =IF(F33="% v/v",$D$3*1000*E33/100,E33*$D$3/Inputs!$B$9) -> 1.875 | H33: x
A34: 16 | B34: Flute B | C34: A | D34: Soprano 500 | E34: 125 | F34: ml/ha | G34: =IF(F34="% v/v",$D$3*1000*E34/100,E34*$D$3/Inputs!$B$9) -> 1.875 | H34: x
A35: 17 | B35: Experimental 2 BL | C35: A | D35: Soprano 500 | E35: 125 | F35: ml/ha | G35: =IF(F35="% v/v",$D$3*1000*E35/100,E35*$D$3/Inputs!$B$9) -> 1.875 | H35: x
A36: 18 | B36: Experimental 2 BH | C36: A | D36: Soprano 500 | E36: 125 | F36: ml/ha | G36: =IF(F36="% v/v",$D$3*1000*E36/100,E36*$D$3/Inputs!$B$9) -> 1.875 | H36: x
A37: 19 | B37: Experimental 3 B | C37: A | D37: Soprano 500 | E37: 125 | F37: ml/ha | G37: =IF(F37="% v/v",$D$3*1000*E37/100,E37*$D$3/Inputs!$B$9) -> 1.875 | H37: x
A38: 20 | B38: Experimental 4 B | C38: A | D38: Soprano 500 | E38: 125 | F38: ml/ha | G38: =IF(F38="% v/v",$D$3*1000*E38/100,E38*$D$3/Inputs!$B$9) -> 1.875 | H38: x
A39: 21 | B39: Marvis A+B | C39: A | D39: Marvis Star | E39: 500 | F39: ml/ha | G39: =IF(F39="% v/v",$D$3*1000*E39/100,E39*$D$3/Inputs!$B$9) -> 7.5 | H39: x
A40: 22 | B40: Marvis A | C40: A | D40: Marvis Star | E40: 500 | F40: ml/ha | G40: =IF(F40="% v/v",$D$3*1000*E40/100,E40*$D$3/Inputs!$B$9) -> 7.5 | H40: x
A41: 23 | B41: Balaya A | C41: A | D41: Balaya | E41: 750 | F41: ml/ha | G41: =IF(F41="% v/v",$D$3*1000*E41/100,E41*$D$3/Inputs!$B$9) -> 11.25 | H41: x
...
