Workbook

Sheet Collated (corrected)
A1: AGnVET Junee — Collated Assessment (Wheat + Canola, ARM-corrected)
A2: 192 plots · Ryegrass/m² = (ARG Q1 + ARG Q2) × 5 (two 0.1 m² quadrats) · treatments validated against ARM — wheat May-14 map, canola Jun-1 tour report
A3: Crop | B3: Plot # | C3: Block | D3: Trt # | E3: Treatment | F3: App A (IBS) | G3: App B (EPE/Post) | H3: Phytotox % | I3: ARG Q1 | J3: ARG Q2 | K3: Ryegrass /m² | L3: Plants/m | M3: Assessor | N3: Photo? | O3: Notes / Observations
A4: Wheat | B4: 101 | C4: 1 | D4: 7 | E4: Spruce | F4: Spruce 500 mL/ha | G4: — | H4: 5 | I4: 16 | J4: 25 | K4: =(I4+J4)*5 -> 205 | L4: 42
A5: Wheat | B5: 102 | C5: 1 | D5: 27 | E5: Mateno Complete (post) | F5: — | G5: Mateno Complete 1000 mL/ha | H5: 10 | I5: 42 | J5: 24 | K5: =(I5+J5)*5 -> 330 | L5: 25
A6: Wheat | B6: 103 | C6: 1 | D6: 24 | E6: Overwatch (post) | F6: — | G6: Overwatch 1250 mL/ha | H6: 70 | I6: 24 | J6: 32 | K6: =(I6+J6)*5 -> 280 | L6: 28
A7: Wheat | B7: 104 | C7: 1 | D7: 17 | E7: TriflurX + Syrexon 1700 | F7: TriflurX 2000 mL/ha | G7: Syrexon 1700 mL/ha | H7: 50 | I7: 12 | J7: 7 | K7: =(I7+J7)*5 -> 95 | L7: 32
A8: Wheat | B8: 105 | C8: 1 | D8: 11 | E8: Voraxor + Sakura | F8: Voraxor 200 mL/ha + Sakura 118 g/ha | G8: — | H8: 5 | I8: 28 | J8: 28 | K8: =(I8+J8)*5 -> 280 | L8: 37
A9: Wheat | B9: 106 | C9: 1 | D9: 20 | E9: TriflurX + Mateno | F9: TriflurX 2000 mL/ha | G9: Mateno Complete 1000 mL/ha | H9: 0 | I9: 6 | J9: 7 | K9: =(I9+J9)*5 -> 65 | L9: 33
A10: Wheat | B10: 107 | C10: 1 | D10: 31 | E10: TriflurX + Avadex + Boxer | F10: TriflurX 2000 mL/ha + Avadex 2000 mL/ha | G10: Boxer Gold 3000 mL/ha | H10: 5 | I10: 8 | J10: 6 | K10: =(I10+J10)*5 -> 70 | L10: 28
A11: Wheat | B11: 108 | C11: 1 | D11: 22 | E11: Avadex | F11: Avadex 2000 mL/ha | G11: — | H11: 0 | I11: 17 | J11: 25 | K11: =(I11+J11)*5 -> 210 | L11: 38
A12: Wheat | B12: 201 | C12: 2 | D12: 26 | E12: Terrain Flow + Sakura | F12: Terrain Flow 125 mL/ha + Sakura 118 g/ha | G12: — | H12: 5 | I12: 20 | J12: 28 | K12: =(I12+J12)*5 -> 240 | L12: 42
A13: Wheat | B13: 202 | C13: 2 | D13: 29 | E13: Overwatch + Sakura (post) | F13: Overwatch 1250 mL/ha + Sakura 118 g/ha | G13: — | H13: 15 | I13: 20 | J13: 32 | K13: =(I13+J13)*5 -> 260 | L13: 32
A14: Wheat | B14: 203 | C14: 2 | D14: 21 | E14: TriflurX + Avadex | F14: TriflurX 2000 mL/ha + Avadex 2000 mL/ha | G14: — | H14: 0 | I14: 12 | J14: 8 | K14: =(I14+J14)*5 -> 100 | L14: 27
A15: Wheat | B15: 204 | C15: 2 | D15: 15 | E15: Sakura + Syrexon 1300 | F15: Sakura 118 g/ha | G15: Syrexon 1300 mL/ha | H15: 15 | I15: 15 | J15: 20 | K15: =(I15+J15)*5 -> 175 | L15: 32
... A30: Wheat | B30: 403 | C30: 4 | D30: 32 | E30: Terrain Flow + Sakura (2) | F30: Terrain Flow 125 mL/ha + Sakura 118 g/ha | G30: — | H30: 5 | I30: 11 | J30: 15 | K30: =(I30+J30)*5 -> 130 | L30: 32
A31: Wheat | B31: 404 | C31: 4 | D31: 4 | E31: Luximax | F31: Luximax 500 mL/ha | G31: — | H31: 0 | I31: 10 | J31: 10 | K31: =(I31+J31)*5 -> 100 | L31: 28 | O31: Damage where boom was primed
A32: Wheat | B32: 405 | C32: 4 | D32: 19 | E32: Overwatch + Boxer Gold | F32: Overwatch 1250 mL/ha | G32: Boxer Gold 2500 mL/ha | H32: 10 | I32: 22 | J32: 25 | K32: =(I32+J32)*5 -> 235 | L32: 42
A33: Wheat | B33: 406 | C33: 4 | D33: 1 | E33: CHK | F33: — | G33: — | H33: 0 | I33: 102 | J33: 104 | K33: =(I33+J33)*5 -> 1030 | L33: 32 | O33: Denser ryegrass than neighbouring treatment, suspicion of being an untreated control (labelled 1)
A34: Wheat | B34: 407 | C34: 4 | D34: 16 | E34: Sakura + Syrexon 1700 | F34: Sakura 118 g/ha | G34: Syrexon 1700 mL/ha | H34: 50 | I34: 15 | J34: 18 | K34: =(I34+J34)*5 -> 165 | L34: 42
A35: Wheat | B35: 408 | C35: 4 | D35: 28 | E35: Sakura + Brodal | F35: — | G35: Sakura 118 g/ha + Brodal 132 mL/ha | H35: 30 | I35: 8 | J35: 32 | K35: =(I35+J35)*5 -> 200 | L35: 28
A36: Wheat | B36: 501 | C36: 5 | D36: 12 | E36: Voraxor + Spruce | F36: Voraxor 200 mL/ha + Spruce 500 mL/ha | G36: — | H36: 5 | I36: 10 | J36: 8 | K36: =(I36+J36)*5 -> 90 | L36: 27
A37: Wheat | B37: 502 | C37: 5 | D37: 21 | E37: TriflurX + Avadex | F37: TriflurX 2000 mL/ha + Avadex 2000 mL/ha | G37: — | H37: 0 | I37: 10 | J37: 12 | K37: =(I37+J37)*5 -> 110 | L37: 35
A38: Wheat | B38: 503 | C38: 5 | D38: 6 | E38: Sakura | F38: Sakura 118 g/ha | G38: — | H38: 0 | I38: 13 | J38: 10 | K38: =(I38+J38)*5 -> 115 | L38: 42
A39: Wheat | B39: 504 | C39: 5 | D39: 25 | E39: Arcade + Mateno | F39: Arcade 3000 mL/ha | G39: Mateno Complete 1000 mL/ha | H39: 5 | I39: 15 | J39: 28 | K39: =(I39+J39)*5 -> 215 | L39: 28
A40: Wheat | B40: 505 | C40: 5 | D40: 23 | E40: TriflurX + Avadex + Mateno | F40: TriflurX 2000 mL/ha + Avadex 2000 mL/ha | G40: Mateno Complete 1000 mL/ha | H40: 15 | I40: 8 | J40: 20 | K40: =(I40+J40)*5 -> 140 | L40: 32
A41: Wheat | B41: 506 | C41: 5 | D41: 24 | E41: Overwatch (post) | F41: — | G41: Overwatch 1250 mL/ha | H41: 70 | I41: 35 | J41: 15 | K41: =(I41+J41)*5 -> 250 | L41: 44
A42: Wheat | B42: 507 | C42: 5 | D42: 18 | E42: Overwatch + Mateno | F42: Overwatch 1250 mL/ha | G42: Mateno Complete 1000 mL/ha | H42: 15 | I42: 12 | J42: 22 | K42: =(I42+J42)*5 -> 170 | L42: 28
A43: Wheat | B43: 508 | C43: 5 | D43: 29 | E43: Overwatch + Sakura (post) | F43: Overwatch 1250 mL/ha + Sakura 118 g/ha | G43: — | H43: 5 | I43: 44 | J43: 33 | K43: =(I43+J43)*5 -> 385 | L43: 32 | O43: Large ryegrass numbers
A44: Wheat | B44: 601 | C44: 6 | D44: 17 | E44: TriflurX + Syrexon 1700 | F44: TriflurX 2000 mL/ha | G44: Syrexon 1700 mL/ha | H44: 60 | I44: 34 | J44: 27 | K44: =(I44+J44)*5 -> 305 | L44: 23 | O44: Bleached ryegrass
A45: Wheat | B45: 602 | C45: 6 | D45: 1 | E45: CHK | F45: — | G45: — | H45: 0 | I45: 36 | J45: 53 | K45: =(I45+J45)*5 -> 445 | L45: 23
A46: Wheat | B46: 603 | C46: 6 | D46: 32 | E46: Terrain Flow + Sakura (2) | F46: Terrain Flow 125 mL/ha + Sakura 118 g/ha | G46: — | H46: 0 | I46: 19 | J46: 19 | K46: =(I46+J46)*5 -> 190 | L46: 16
A47: Wheat | B47: 604 | C47: 6 | D47: 10 | E47: Overwatch + Spruce | F47: Overwatch 1250 mL/ha + Spruce 500 mL/ha | G47: — | H47: 0 | I47: 7 | J47: 8 | K47: =(I47+J47)*5 -> 75 | L47: 24
A48: Wheat | B48: 605 | C48: 6 | D48: 30 | E48: Sakura split dose | F48: Sakura 100 g/ha | G48: Sakura 30 g/ha | H48: 0 | I48: 16 | J48: 22 | K48: =(I48+J48)*5 -> 190 | L48: 20
A49: Wheat | B49: 606 | C49: 6 | D49: 11 | E49: Voraxor + Sakura | F49: Voraxor 200 mL/ha + Sakura 118 g/ha | G49: — | H49: 0 | I49: 18 | J49: 16 | K49: =(I49+J49)*5 -> 170 | L49: 16
A50: Wheat | B50: 607 | C50: 6 | D50: 14 | E50: Spruce + Avadex | F50: Spruce 500 mL/ha + Avadex 2000 mL/ha | G50: — | H50: 0 | I50: 25 | J50: 20 | K50: =(I50+J50)*5 -> 225 | L50: 25
A51: Wheat | B51: 608 | C51: 6 | D51: 5 | E51: Overwatch | F51: Overwatch 1250 mL/ha | G51: — | H51: 5 | I51: 28 | J51: 22 | K51: =(I51+J51)*5 -> 250 | L51: 28
A52: Wheat | B52: 701 | C52: 7 | D52: 16 | E52: Sakura + Syrexon 1700 | F52: Sakura 118 g/ha | G52: Syrexon 1700 mL/ha | H52: 60 | I52: 28 | J52: 7 | K52: =(I52+J52)*5 -> 175 | L52: 25
A53: Wheat | B53: 702 | C53: 7 | D53: 22 | E53: Avadex | F53: Avadex 2000 mL/ha | G53: — | H53: 0 | I53: 11 | J53: 6 | K53: =(I53+J53)*5 -> 85 | L53: 24
A54: Wheat | B54: 703 | C54: 7 | D54: 31 | E54: TriflurX + Avadex + Boxer | F54: TriflurX 2000 mL/ha + Avadex 2000 mL/ha | G54: Boxer Gold 3000 mL/ha | H54: 0 | I54: 5 | J54: 6 | K54: =(I54+J54)*5 -> 55 | L54: 16
...

Sheet Treatment Data
A1: AGnVET Junee — Treatment Data (means across 3 reps, ARM-corrected)
A2: Live from the Collated tab · Ryegrass/m² = (Q1+Q2)×5 · % control = reduction vs untreated CHK (Trt 1) within crop | L2: CHK mean ryegrass/m²
A3: Crop | B3: Trt # | C3: Treatment | D3: App A (IBS) | E3: App B (EPE/Post) | F3: n | G3: Mean Ryegrass /m² | H3: Mean Phytotox % | I3: Mean Plants/m | J3: % RG control vs CHK | K3: Plants/m² | L3: Wheat | M3: =AVERAGEIFS('Collated (corrected)'!$K$4:$K$195,'Collated (corrected)'!$A$4:$A$195,"Wheat",'Collated (corrected)'!$D$4:$D$195,1) -> 558.33333 | T3: Crop CHK Plants/m²
A4: Wheat | B4: 1 | C4: CHK | D4: — | E4: — | F4: =COUNTIFS('Collated (corrected)'!$A$4:$A$195,$A4,'Collated (corrected)'!$D$4:$D$195,$B4) -> 3 | G4: =AVERAGEIFS('Collated (corrected)'!$K$4:$K$195,'Collated (corrected)'!$A$4:$A$195,$A4,'Collated (corrected)'!$D$4:$D$195,$B4) -> 558.33333 | H4: =AVERAGEIFS('Collated (corrected)'!$H$4:$H$195,'Collated (corrected)'!$A$4:$A$195,$A4,'Collated (corrected)'!$D$4:$D$195,$B4) -> 0 | I4: =AVERAGEIFS('Collated (corrected)'!$L$4:$L$195,'Collated (corrected)'!$A$4:$A$195,$A4,'Collated (corrected)'!$D$4:$D$195,$B4) -> 25.333333 | J4: =IF($B4=1,"",($M$3-G4)/$M$3) | K4: =I4*$B$71 -> 101.33333 | L4: Canola | M4: =AVERAGEIFS('Collated (corrected)'!$K$4:$K$195,'Collated (corrected)'!$A$4:$A$195,"Canola",'Collated (corrected)'!$D$4:$D$195,1) -> 591.66667 | T4: =IF($A4="Wheat",$M$7,$M$8) -> 101.33333
A5: Wheat | B5: 2 | C5: Boxer Gold | D5: Boxer Gold 2500 mL/ha | E5: — | F5: =COUNTIFS('Collated (corrected)'!$A$4:$A$195,$A5,'Collated (corrected)'!$D$4:$D$195,$B5) -> 3 | G5: =AVERAGEIFS('Collated (corrected)'!$K$4:$K$195,'Collated (corrected)'!$A$4:$A$195,$A5,'Collated (corrected)'!$D$4:$D$195,$B5) -> 113.33333 | H5: =AVERAGEIFS('Collated (corrected)'!$H$4:$H$195,'Collated (corrected)'!$A$4:$A$195,$A5,'Collated (corrected)'!$D$4:$D$195,$B5) -> 1.6666667 | I5: =AVERAGEIFS('Collated (corrected)'!$L$4:$L$195,'Collated (corrected)'!$A$4:$A$195,$A5,'Collated (corrected)'!$D$4:$D$195,$B5) -> 25.666667 | J5: =IF($B5=1,"",($M$3-G5)/$M$3) -> 0.79701493 | K5: =I5*$B$71 -> 102.66667 | T5: =IF($A5="Wheat",$M$7,$M$8) -> 101.33333
A6: Wheat | B6: 3 | C6: TriflurX | D6: TriflurX 2000 mL/ha | E6: — | F6: =COUNTIFS('Collated (corrected)'!$A$4:$A$195,$A6,'Collated (corrected)'!$D$4:$D$195,$B6) -> 3 | G6: =AVERAGEIFS('Collated (corrected)'!$K$4:$K$195,'Collated (corrected)'!$A$4:$A$195,$A6,'Collated (corrected)'!$D$4:$D$195,$B6) -> 113.33333 | H6: =AVERAGEIFS('Collated (corrected)'!$H$4:$H$195,'Collated (corrected)'!$A$4:$A$195,$A6,'Collated (corrected)'!$D$4:$D$195,$B6) -> 0 | I6: =AVERAGEIFS('Collated (corrected)'!$L$4:$L$195,'Collated (corrected)'!$A$4:$A$195,$A6,'Collated (corrected)'!$D$4:$D$195,$B6) -> 25.333333 | J6: =IF($B6=1,"",($M$3-G6)/$M$3) -> 0.79701493 | K6: =I6*$B$71 -> 101.33333 | L6: CHK mean plants/m² | T6: =IF($A6="Wheat",$M$7,$M$8) -> 101.33333
A7: Wheat | B7: 4 | C7: Luximax | D7: Luximax 500 mL/ha | E7: — | F7: =COUNTIFS('Collated (corrected)'!$A$4:$A$195,$A7,'Collated (corrected)'!$D$4:$D$195,$B7) -> 3 | G7: =AVERAGEIFS('Collated (corrected)'!$K$4:$K$195,'Collated (corrected)'!$A$4:$A$195,$A7,'Collated (corrected)'!$D$4:$D$195,$B7) -> 110 | H7: =AVERAGEIFS('Collated (corrected)'!$H$4:$H$195,'Collated (corrected)'!$A$4:$A$195,$A7,'Collated (corrected)'!$D$4:$D$195,$B7) -> 2 | I7: =AVERAGEIFS('Collated (corrected)'!$L$4:$L$195,'Collated (corrected)'!$A$4:$A$195,$A7,'Collated (corrected)'!$D$4:$D$195,$B7) -> 18.333333 | J7: =IF($B7=1,"",($M$3-G7)/$M$3) -> 0.80298507 | K7: =I7*$B$71 -> 73.333333 | L7: Wheat | M7: =K4 -> 101.33333 | T7: =IF($A7="Wheat",$M$7,$M$8) -> 101.33333
A8: Wheat | B8: 5 | C8: Overwatch | D8: Overwatch 1250 mL/ha | E8: — | F8: =COUNTIFS('Collated (corrected)'!$A$4:$A$195,$A8,'Collated (corrected)'!$D$4:$D$195,$B8) -> 3 | G8: =AVERAGEIFS('Collated (corrected)'!$K$4:$K$195,'Collated (corrected)'!$A$4:$A$195,$A8,'Collated (corrected)'!$D$4:$D$195,$B8) -> 191.66667 | H8: =AVERAGEIFS('Collated (corrected)'!$H$4:$H$195,'Collated (corrected)'!$A$4:$A$195,$A8,'Collated (corrected)'!$D$4:$D$195,$B8) -> 3.3333333 | I8: =AVERAGEIFS('Collated (corrected)'!$L$4:$L$195,'Collated (corrected)'!$A$4:$A$195,$A8,'Collated (corrected)'!$D$4:$D$195,$B8) -> 24.666667 | J8: =IF($B8=1,"",($M$3-G8)/$M$3) -> 0.65671642 | K8: =I8*$B$71 -> 98.666667 | L8: Canola | M8: =K36 -> 69.333333 | T8: =IF($A8="Wheat",$M$7,$M$8) -> 101.33333
A9: Wheat | B9: 6 | C9: Sakura | D9: Sakura 118 g/ha | E9: — | F9: =COUNTIFS('Collated (corrected)'!$A$4:$A$195,$A9,'Collated (corrected)'!$D$4:$D$195,$B9) -> 3 | G9: =AVERAGEIFS('Collated (corrected)'!$K$4:$K$195,'Collated (corrected)'!$A$4:$A$195,$A9,'Collated (corrected)'!$D$4:$D$195,$B9) -> 161.66667 | H9: =AVERAGEIFS('Collated (corrected)'!$H$4:$H$195,'Collated (corrected)'!$A$4:$A$195,$A9,'Collated (corrected)'!$D$4:$D$195,$B9) -> 0 | I9: =AVERAGEIFS('Collated (corrected)'!$L$4:$L$195,'Collated (corrected)'!$A$4:$A$195,$A9,'Collated (corrected)'!$D$4:$D$195,$B9) -> 32.666667 | J9: =IF($B9=1,"",($M$3-G9)/$M$3) -> 0.71044776 | K9: =I9*$B$71 -> 130.66667 | T9: =IF($A9="Wheat",$M$7,$M$8) -> 101.33333
A10: Wheat | B10: 7 | C10: Spruce | D10: Spruce 500 mL/ha | E10: — | F10: =COUNTIFS('Collated (corrected)'!$A$4:$A$195,$A10,'Collated (corrected)'!$D$4:$D$195,$B10) -> 3 | G10: =AVERAGEIFS('Collated (corrected)'!$K$4:$K$195,'Collated (corrected)'!$A$4:$A$195,$A10,'Collated (corrected)'!$D$4:$D$195,$B10) -> 185 | H10: =AVERAGEIFS('Collated (corrected)'!$H$4:$H$195,'Collated (corrected)'!$A$4:$A$195,$A10,'Collated (corrected)'!$D$4:$D$195,$B10) -> 1.6666667 | I10: =AVERAGEIFS('Collated (corrected)'!$L$4:$L$195,'Collated (corrected)'!$A$4:$A$195,$A10,'Collated (corrected)'!$D$4:$D$195,$B10) -> 30.333333 | J10: =IF($B10=1,"",($M$3-G10)/$M$3) -> 0.66865672 | K10: =I10*$B$71 -> 121.33333 | T10: =IF($A10="Wheat",$M$7,$M$8) -> 101.33333
A11: Wheat | B11: 8 | C11: Mateno Complete | D11: Mateno Complete 1000 mL/ha | E11: — | F11: =COUNTIFS('Collated (corrected)'!$A$4:$A$195,$A11,'Collated (corrected)'!$D$4:$D$195,$B11) -> 3 | G11: =AVERAGEIFS('Collated (corrected)'!$K$4:$K$195,'Collated (corrected)'!$A$4:$A$195,$A11,'Collated (corrected)'!$D$4:$D$195,$B11) -> 151.66667 | H11: =AVERAGEIFS('Collated (corrected)'!$H$4:$H$195,'Collated (corrected)'!$A$4:$A$195,$A11,'Collated (corrected)'!$D$4:$D$195,$B11) -> 0 | I11: =AVERAGEIFS('Collated (corrected)'!$L$4:$L$195,'Collated (corrected)'!$A$4:$A$195,$A11,'Collated (corrected)'!$D$4:$D$195,$B11) -> 27 | J11: =IF($B11=1,"",($M$3-G11)/$M$3) -> 0.72835821 | K11: =I11*$B$71 -> 108 | T11: =IF($A11="Wheat",$M$7,$M$8) -> 101.33333
A12: Wheat | B12: 9 | C12: Overwatch + Sakura | D12: Overwatch 1250 mL/ha + Sakura 118 g/ha | E12: — | F12: =COUNTIFS('Collated (corrected)'!$A$4:$A$195,$A12,'Collated (corrected)'!$D$4:$D$195,$B12) -> 3 | G12: =AVERAGEIFS('Collated (corrected)'!$K$4:$K$195,'Collated (corrected)'!$A$4:$A$195,$A12,'Collated (corrected)'!$D$4:$D$195,$B12) -> 106.66667 | H12: =AVERAGEIFS('Collated (corrected)'!$H$4:$H$195,'Collated (corrected)'!$A$4:$A$195,$A12,'Collated (corrected)'!$D$4:$D$195,$B12) -> 1.6666667 | I12: =AVERAGEIFS('Collated (corrected)'!$L$4:$L$195,'Collated (corrected)'!$A$4:$A$195,$A12,'Collated (corrected)'!$D$4:$D$195,$B12) -> 22.666667 | J12: =IF($B12=1,"",($M$3-G12)/$M$3) -> 0.80895522 | K12: =I12*$B$71 -> 90.666667 | T12: =IF($A12="Wheat",$M$7,$M$8) -> 101.33333
A13: Wheat | B13: 10 | C13: Overwatch + Spruce | D13: Overwatch 1250 mL/ha + Spruce 500 mL/ha | E13: — | F13: =COUNTIFS('Collated (corrected)'!$A$4:$A$195,$A13,'Collated (corrected)'!$D$4:$D$195,$B13) -> 3 | G13: =AVERAGEIFS('Collated (corrected)'!$K$4:$K$195,'Collated (corrected)'!$A$4:$A$195,$A13,'Collated (corrected)'!$D$4:$D$195,$B13) -> 81.666667 | H13: =AVERAGEIFS('Collated (corrected)'!$H$4:$H$195,'Collated (corrected)'!$A$4:$A$195,$A13,'Collated (corrected)'!$D$4:$D$195,$B13) -> 3.3333333 | I13: =AVERAGEIFS('Collated (corrected)'!$L$4:$L$195,'Collated (corrected)'!$A$4:$A$195,$A13,'Collated (corrected)'!$D$4:$D$195,$B13) -> 22.666667 | J13: =IF($B13=1,"",($M$3-G13)/$M$3) -> 0.85373134 | K13: =I13*$B$71 -> 90.666667 | T13: =IF($A13="Wheat",$M$7,$M$8) -> 101.33333
A14: Wheat | B14: 11 | C14: Voraxor + Sakura | D14: Voraxor 200 mL/ha + Sakura 118 g/ha | E14: — | F14: =COUNTIFS('Collated (corrected)'!$A$4:$A$195,$A14,'Collated (corrected)'!$D$4:$D$195,$B14) -> 3 | G14: =AVERAGEIFS('Collated (corrected)'!$K$4:$K$195,'Collated (corrected)'!$A$4:$A$195,$A14,'Collated (corrected)'!$D$4:$D$195,$B14) -> 170 | H14: =AVERAGEIFS('Collated (corrected)'!$H$4:$H$195,'Collated (corrected)'!$A$4:$A$195,$A14,'Collated (corrected)'!$D$4:$D$195,$B14) -> 1.6666667 | I14: =AVERAGEIFS('Collated (corrected)'!$L$4:$L$195,'Collated (corrected)'!$A$4:$A$195,$A14,'Collated (corrected)'!$D$4:$D$195,$B14) -> 23 | J14: =IF($B14=1,"",($M$3-G14)/$M$3) -> 0.69552239 | K14: =I14*$B$71 -> 92 | T14: =IF($A14="Wheat",$M$7,$M$8) -> 101.33333
A15: Wheat | B15: 12 | C15: Voraxor + Spruce | D15: Voraxor 200 mL/ha + Spruce 500 mL/ha | E15: — | F15: =COUNTIFS('Collated (corrected)'!$A$4:$A$195,$A15,'Collated (corrected)'!$D$4:$D$195,$B15) -> 3 | G15: =AVERAGEIFS('Collated (corrected)'!$K$4:$K$195,'Collated (corrected)'!$A$4:$A$195,$A15,'Collated (corrected)'!$D$4:$D$195,$B15) -> 123.33333 | H15: =AVERAGEIFS('Collated (corrected)'!$H$4:$H$195,'Collated (corrected)'!$A$4:$A$195,$A15,'Collated (corrected)'!$D$4:$D$195,$B15) -> 3.3333333 | I15: =AVERAGEIFS('Collated (corrected)'!$L$4:$L$195,'Collated (corrected)'!$A$4:$A$195,$A15,'Collated (corrected)'!$D$4:$D$195,$B15) -> 31.666667 | J15: =IF($B15=1,"",($M$3-G15)/$M$3) -> 0.77910448 | K15: =I15*$B$71 -> 126.66667 | T15: =IF($A15="Wheat",$M$7,$M$8) -> 101.33333
A16: Wheat | B16: 13 | C16: Sakura + Avadex | D16: Sakura 118 g/ha + Avadex 2000 mL/ha | E16: — | F16: =COUNTIFS('Collated (corrected)'!$A$4:$A$195,$A16,'Collated (corrected)'!$D$4:$D$195,$B16) -> 3 | G16: =AVERAGEIFS('Collated (corrected)'!$K$4:$K$195,'Collated (corrected)'!$A$4:$A$195,$A16,'Collated (corrected)'!$D$4:$D$195,$B16) -> 73.333333 | H16: =AVERAGEIFS('Collated (corrected)'!$H$4:$H$195,'Collated (corrected)'!$A$4:$A$195,$A16,'Collated (corrected)'!$D$4:$D$195,$B16) -> 0 | I16: =AVERAGEIFS('Collated (corrected)'!$L$4:$L$195,'Collated (corrected)'!$A$4:$A$195,$A16,'Collated (corrected)'!$D$4:$D$195,$B16) -> 27 | J16: =IF($B16=1,"",($M$3-G16)/$M$3) -> 0.86865672 | K16: =I16*$B$71 -> 108 | T16: =IF($A16="Wheat",$M$7,$M$8) -> 101.33333
A17: Wheat | B17: 14 | C17: Spruce + Avadex | D17: Spruce 500 mL/ha + Avadex 2000 mL/ha | E17: — | F17: =COUNTIFS('Collated (corrected)'!$A$4:$A$195,$A17,'Collated (corrected)'!$D$4:$D$195,$B17) -> 3 | G17: =AVERAGEIFS('Collated (corrected)'!$K$4:$K$195,'Collated (corrected)'!$A$4:$A$195,$A17,'Collated (corrected)'!$D$4:$D$195,$B17) -> 138.33333 | H17: =AVERAGEIFS('Collated (corrected)'!$H$4:$H$195,'Collated (corrected)'!$A$4:$A$195,$A17,'Collated (corrected)'!$D$4:$D$195,$B17) -> 3.3333333 | I17: =AVERAGEIFS('Collated (corrected)'!$L$4:$L$195,'Collated (corrected)'!$A$4:$A$195,$A17,'Collated (corrected)'!$D$4:$D$195,$B17) -> 25 | J17: =IF($B17=1,"",($M$3-G17)/$M$3) -> 0.75223881 | K17: =I17*$B$71 -> 100 | T17: =IF($A17="Wheat",$M$7,$M$8) -> 101.33333
A18: Wheat | B18: 15 | C18: Sakura + Syrexon 1300 | D18: Sakura 118 g/ha | E18: Syrexon 1300 mL/ha | F18: =COUNTIFS('Collated (corrected)'!$A$4:$A$195,$A18,'Collated (corrected)'!$D$4:$D$195,$B18) -> 3 | G18: =AVERAGEIFS('Collated (corrected)'!$K$4:$K$195,'Collated (corrected)'!$A$4:$A$195,$A18,'Collated (corrected)'!$D$4:$D$195,$B18) -> 166.66667 | H18: =AVERAGEIFS('Collated (corrected)'!$H$4:$H$195,'Collated (corrected)'!$A$4:$A$195,$A18,'Collated (corrected)'!$D$4:$D$195,$B18) -> 5 | I18: =AVERAGEIFS('Collated (corrected)'!$L$4:$L$195,'Collated (corrected)'!$A$4:$A$195,$A18,'Collated (corrected)'!$D$4:$D$195,$B18) -> 25.666667 | J18: =IF($B18=1,"",($M$3-G18)/$M$3) -> 0.70149254 | K18: =I18*$B$71 -> 102.66667 | T18: =IF($A18="Wheat",$M$7,$M$8) -> 101.33333
A19: Wheat | B19: 16 | C19: Sakura + Syrexon 1700 | D19: Sakura 118 g/ha | E19: Syrexon 1700 mL/ha | F19: =COUNTIFS('Collated (corrected)'!$A$4:$A$195,$A19,'Collated (corrected)'!$D$4:$D$195,$B19) -> 3 | G19: =AVERAGEIFS('Collated (corrected)'!$K$4:$K$195,'Collated (corrected)'!$A$4:$A$195,$A19,'Collated (corrected)'!$D$4:$D$195,$B19) -> 138.33333 | H19: =AVERAGEIFS('Collated (corrected)'!$H$4:$H$195,'Collated (corrected)'!$A$4:$A$195,$A19,'Collated (corrected)'!$D$4:$D$195,$B19) -> 63.333333 | I19: =AVERAGEIFS('Collated (corrected)'!$L$4:$L$195,'Collated (corrected)'!$A$4:$A$195,$A19,'Collated (corrected)'!$D$4:$D$195,$B19) -> 28.666667 | J19: =IF($B19=1,"",($M$3-G19)/$M$3) -> 0.75223881 | K19: =I19*$B$71 -> 114.66667 | T19: =IF($A19="Wheat",$M$7,$M$8) -> 101.33333
A20: Wheat | B20: 17 | C20: TriflurX + Syrexon 1700 | D20: TriflurX 2000 mL/ha | E20: Syrexon 1700 mL/ha | F20: =COUNTIFS('Collated (corrected)'!$A$4:$A$195,$A20,'Collated (corrected)'!$D$4:$D$195,$B20) -> 3 | G20: =AVERAGEIFS('Collated (corrected)'!$K$4:$K$195,'Collated (corrected)'!$A$4:$A$195,$A20,'Collated (corrected)'!$D$4:$D$195,$B20) -> 183.33333 | H20: =AVERAGEIFS('Collated (corrected)'!$H$4:$H$195,'Collated (corrected)'!$A$4:$A$195,$A20,'Collated (corrected)'!$D$4:$D$195,$B20) -> 56.666667 | I20: =AVERAGEIFS('Collated (corrected)'!$L$4:$L$195,'Collated (corrected)'!$A$4:$A$195,$A20,'Collated (corrected)'!$D$4:$D$195,$B20) -> 25 | J20: =IF($B20=1,"",($M$3-G20)/$M$3) -> 0.67164179 | K20: =I20*$B$71 -> 100 | T20: =IF($A20="Wheat",$M$7,$M$8) -> 101.33333
... A35: Wheat | B35: 32 | C35: Terrain Flow + Sakura (2) | D35: Terrain Flow 125 mL/ha + Sakura 118 g/ha | E35: — | F35: =COUNTIFS('Collated (corrected)'!$A$4:$A$195,$A35,'Collated (corrected)'!$D$4:$D$195,$B35) -> 3 | G35: =AVERAGEIFS('Collated (corrected)'!$K$4:$K$195,'Collated (corrected)'!$A$4:$A$195,$A35,'Collated (corrected)'!$D$4:$D$195,$B35) -> 185 | H35: =AVERAGEIFS('Collated (corrected)'!$H$4:$H$195,'Collated (corrected)'!$A$4:$A$195,$A35,'Collated (corrected)'!$D$4:$D$195,$B35) -> 1.6666667 | I35: =AVERAGEIFS('Collated (corrected)'!$L$4:$L$195,'Collated (corrected)'!$A$4:$A$195,$A35,'Collated (corrected)'!$D$4:$D$195,$B35) -> 25 | J35: =IF($B35=1,"",($M$3-G35)/$M$3) -> 0.66865672 | K35: =I35*$B$71 -> 100 | T35: =IF($A35="Wheat",$M$7,$M$8) -> 101.33333
A36: Canola | B36: 1 | C36: CHK | D36: — | E36: — | F36: =COUNTIFS('Collated (corrected)'!$A$4:$A$195,$A36,'Collated (corrected)'!$D$4:$D$195,$B36) -> 3 | G36: =AVERAGEIFS('Collated (corrected)'!$K$4:$K$195,'Collated (corrected)'!$A$4:$A$195,$A36,'Collated (corrected)'!$D$4:$D$195,$B36) -> 591.66667 | H36: =AVERAGEIFS('Collated (corrected)'!$H$4:$H$195,'Collated (corrected)'!$A$4:$A$195,$A36,'Collated (corrected)'!$D$4:$D$195,$B36) -> 0 | I36: =AVERAGEIFS('Collated (corrected)'!$L$4:$L$195,'Collated (corrected)'!$A$4:$A$195,$A36,'Collated (corrected)'!$D$4:$D$195,$B36) -> 17.333333 | J36: =IF($B36=1,"",($M$4-G36)/$M$4) | K36: =I36*$B$71 -> 69.333333 | T36: =IF($A36="Wheat",$M$7,$M$8) -> 69.333333
A37: Canola | B37: 2 | C37: Devrinol Advanced | D37: Devrinol Advanced 3000 mL/ha | E37: — | F37: =COUNTIFS('Collated (corrected)'!$A$4:$A$195,$A37,'Collated (corrected)'!$D$4:$D$195,$B37) -> 3 | G37: =AVERAGEIFS('Collated (corrected)'!$K$4:$K$195,'Collated (corrected)'!$A$4:$A$195,$A37,'Collated (corrected)'!$D$4:$D$195,$B37) -> 163.33333 | H37: =AVERAGEIFS('Collated (corrected)'!$H$4:$H$195,'Collated (corrected)'!$A$4:$A$195,$A37,'Collated (corrected)'!$D$4:$D$195,$B37) -> 0 | I37: =AVERAGEIFS('Collated (corrected)'!$L$4:$L$195,'Collated (corrected)'!$A$4:$A$195,$A37,'Collated (corrected)'!$D$4:$D$195,$B37) -> 10 | J37: =IF($B37=1,"",($M$4-G37)/$M$4) -> 0.72394366 | K37: =I37*$B$71 -> 40 | T37: =IF($A37="Wheat",$M$7,$M$8) -> 69.333333
A38: Canola | B38: 3 | C38: Overwatch | D38: Overwatch 1250 mL/ha | E38: — | F38: =COUNTIFS('Collated (corrected)'!$A$4:$A$195,$A38,'Collated (corrected)'!$D$4:$D$195,$B38) -> 3 | G38: =AVERAGEIFS('Collated (corrected)'!$K$4:$K$195,'Collated (corrected)'!$A$4:$A$195,$A38,'Collated (corrected)'!$D$4:$D$195,$B38) -> 180 | H38: =AVERAGEIFS('Collated (corrected)'!$H$4:$H$195,'Collated (corrected)'!$A$4:$A$195,$A38,'Collated (corrected)'!$D$4:$D$195,$B38) -> 0 | I38: =AVERAGEIFS('Collated (corrected)'!$L$4:$L$195,'Collated (corrected)'!$A$4:$A$195,$A38,'Collated (corrected)'!$D$4:$D$195,$B38) -> 18.666667 | J38: =IF($B38=1,"",($M$4-G38)/$M$4) -> 0.69577465 | K38: =I38*$B$71 -> 74.666667 | T38: =IF($A38="Wheat",$M$7,$M$8) -> 69.333333
A39: Canola | B39: 4 | C39: Luximax | D39: Luximax 500 mL/ha | E39: — | F39: =COUNTIFS('Collated (corrected)'!$A$4:$A$195,$A39,'Collated (corrected)'!$D$4:$D$195,$B39) -> 3 | G39: =AVERAGEIFS('Collated (corrected)'!$K$4:$K$195,'Collated (corrected)'!$A$4:$A$195,$A39,'Collated (corrected)'!$D$4:$D$195,$B39) -> 146.66667 | H39: =AVERAGEIFS('Collated (corrected)'!$H$4:$H$195,'Collated (corrected)'!$A$4:$A$195,$A39,'Collated (corrected)'!$D$4:$D$195,$B39) -> 0 | I39: =AVERAGEIFS('Collated (corrected)'!$L$4:$L$195,'Collated (corrected)'!$A$4:$A$195,$A39,'Collated (corrected)'!$D$4:$D$195,$B39) -> 13 | J39: =IF($B39=1,"",($M$4-G39)/$M$4) -> 0.75211268 | K39: =I39*$B$71 -> 52 | T39: =IF($A39="Wheat",$M$7,$M$8) -> 69.333333
A40: Canola | B40: 5 | C40: Rustler | D40: Rustler 1000 mL/ha | E40: — | F40: =COUNTIFS('Collated (corrected)'!$A$4:$A$195,$A40,'Collated (corrected)'!$D$4:$D$195,$B40) -> 3 | G40: =AVERAGEIFS('Collated (corrected)'!$K$4:$K$195,'Collated (corrected)'!$A$4:$A$195,$A40,'Collated (corrected)'!$D$4:$D$195,$B40) -> 98.333333 | H40: =AVERAGEIFS('Collated (corrected)'!$H$4:$H$195,'Collated (corrected)'!$A$4:$A$195,$A40,'Collated (corrected)'!$D$4:$D$195,$B40) -> 0 | I40: =AVERAGEIFS('Collated (corrected)'!$L$4:$L$195,'Collated (corrected)'!$A$4:$A$195,$A40,'Collated (corrected)'!$D$4:$D$195,$B40) -> 15 | J40: =IF($B40=1,"",($M$4-G40)/$M$4) -> 0.83380282 | K40: =I40*$B$71 -> 60 | T40: =IF($A40="Wheat",$M$7,$M$8) -> 69.333333
A41: Canola | B41: 6 | C41: Tenet | D41: Tenet 1500 mL/ha | E41: — | F41: =COUNTIFS('Collated (corrected)'!$A$4:$A$195,$A41,'Collated (corrected)'!$D$4:$D$195,$B41) -> 3 | G41: =AVERAGEIFS('Collated (corrected)'!$K$4:$K$195,'Collated (corrected)'!$A$4:$A$195,$A41,'Collated (corrected)'!$D$4:$D$195,$B41) -> 203.33333 | H41: =AVERAGEIFS('Collated (corrected)'!$H$4:$H$195,'Collated (corrected)'!$A$4:$A$195,$A41,'Collated (corrected)'!$D$4:$D$195,$B41) -> 0 | I41: =AVERAGEIFS('Collated (corrected)'!$L$4:$L$195,'Collated (corrected)'!$A$4:$A$195,$A41,'Collated (corrected)'!$D$4:$D$195,$B41) -> 13.333333 | J41: =IF($B41=1,"",($M$4-G41)/$M$4) -> 0.65633803 | K41: =I41*$B$71 -> 53.333333 | T41: =IF($A41="Wheat",$M$7,$M$8) -> 69.333333
A42: Canola | B42: 7 | C42: TriflurX | D42: TriflurX 2000 mL/ha | E42: — | F42: =COUNTIFS('Collated (corrected)'!$A$4:$A$195,$A42,'Collated (corrected)'!$D$4:$D$195,$B42) -> 3 | G42: =AVERAGEIFS('Collated (corrected)'!$K$4:$K$195,'Collated (corrected)'!$A$4:$A$195,$A42,'Collated (corrected)'!$D$4:$D$195,$B42) -> 125 | H42: =AVERAGEIFS('Collated (corrected)'!$H$4:$H$195,'Collated (corrected)'!$A$4:$A$195,$A42,'Collated (corrected)'!$D$4:$D$195,$B42) -> 0 | I42: =AVERAGEIFS('Collated (corrected)'!$L$4:$L$195,'Collated (corrected)'!$A$4:$A$195,$A42,'Collated (corrected)'!$D$4:$D$195,$B42) -> 16.333333 | J42: =IF($B42=1,"",($M$4-G42)/$M$4) -> 0.78873239 | K42: =I42*$B$71 -> 65.333333 | T42: =IF($A42="Wheat",$M$7,$M$8) -> 69.333333
A43: Canola | B43: 8 | C43: TriflurX + Plat Xtra | D43: TriflurX 2000 mL/ha | E43: Plat Xtra 360 330 mL/ha + Hasten 1% | F43: =COUNTIFS('Collated (corrected)'!$A$4:$A$195,$A43,'Collated (corrected)'!$D$4:$D$195,$B43) -> 3 | G43: =AVERAGEIFS('Collated (corrected)'!$K$4:$K$195,'Collated (corrected)'!$A$4:$A$195,$A43,'Collated (corrected)'!$D$4:$D$195,$B43) -> 63.333333 | H43: =AVERAGEIFS('Collated (corrected)'!$H$4:$H$195,'Collated (corrected)'!$A$4:$A$195,$A43,'Collated (corrected)'!$D$4:$D$195,$B43) -> 0 | I43: =AVERAGEIFS('Collated (corrected)'!$L$4:$L$195,'Collated (corrected)'!$A$4:$A$195,$A43,'Collated (corrected)'!$D$4:$D$195,$B43) -> 19 | J43: =IF($B43=1,"",($M$4-G43)/$M$4) -> 0.89295775 | K43: =I43*$B$71 -> 76 | T43: =IF($A43="Wheat",$M$7,$M$8) -> 69.333333
A44: Canola | B44: 9 | C44: Rustler + Plat Xtra | D44: Rustler 1000 mL/ha | E44: Plat Xtra 360 330 mL/ha + Hasten 1% | F44: =COUNTIFS('Collated (corrected)'!$A$4:$A$195,$A44,'Collated (corrected)'!$D$4:$D$195,$B44) -> 3 | G44: =AVERAGEIFS('Collated (corrected)'!$K$4:$K$195,'Collated (corrected)'!$A$4:$A$195,$A44,'Collated (corrected)'!$D$4:$D$195,$B44) -> 41.666667 | H44: =AVERAGEIFS('Collated (corrected)'!$H$4:$H$195,'Collated (corrected)'!$A$4:$A$195,$A44,'Collated (corrected)'!$D$4:$D$195,$B44) -> 5 | I44: =AVERAGEIFS('Collated (corrected)'!$L$4:$L$195,'Collated (corrected)'!$A$4:$A$195,$A44,'Collated (corrected)'!$D$4:$D$195,$B44) -> 17.333333 | J44: =IF($B44=1,"",($M$4-G44)/$M$4) -> 0.92957746 | K44: =I44*$B$71 -> 69.333333 | T44: =IF($A44="Wheat",$M$7,$M$8) -> 69.333333
A45: Canola | B45: 10 | C45: Devrinol Adv + Plat | D45: Devrinol Advanced 3000 mL/ha | E45: Plat Xtra 360 330 mL/ha + Hasten 1% | F45: =COUNTIFS('Collated (corrected)'!$A$4:$A$195,$A45,'Collated (corrected)'!$D$4:$D$195,$B45) -> 3 | G45: =AVERAGEIFS('Collated (corrected)'!$K$4:$K$195,'Collated (corrected)'!$A$4:$A$195,$A45,'Collated (corrected)'!$D$4:$D$195,$B45) -> 110 | H45: =AVERAGEIFS('Collated (corrected)'!$H$4:$H$195,'Collated (corrected)'!$A$4:$A$195,$A45,'Collated (corrected)'!$D$4:$D$195,$B45) -> 0 | I45: =AVERAGEIFS('Collated (corrected)'!$L$4:$L$195,'Collated (corrected)'!$A$4:$A$195,$A45,'Collated (corrected)'!$D$4:$D$195,$B45) -> 17.333333 | J45: =IF($B45=1,"",($M$4-G45)/$M$4) -> 0.81408451 | K45: =I45*$B$71 -> 69.333333 | T45: =IF($A45="Wheat",$M$7,$M$8) -> 69.333333
A46: Canola | B46: 11 | C46: Overwatch + Plat | D46: Overwatch 1250 mL/ha | E46: Plat Xtra 360 330 mL/ha + Hasten 1% | F46: =COUNTIFS('Collated (corrected)'!$A$4:$A$195,$A46,'Collated (corrected)'!$D$4:$D$195,$B46) -> 3 | G46: =AVERAGEIFS('Collated (corrected)'!$K$4:$K$195,'Collated (corrected)'!$A$4:$A$195,$A46,'Collated (corrected)'!$D$4:$D$195,$B46) -> 30 | H46: =AVERAGEIFS('Collated (corrected)'!$H$4:$H$195,'Collated (corrected)'!$A$4:$A$195,$A46,'Collated (corrected)'!$D$4:$D$195,$B46) -> 1.6666667 | I46: =AVERAGEIFS('Collated (corrected)'!$L$4:$L$195,'Collated (corrected)'!$A$4:$A$195,$A46,'Collated (corrected)'!$D$4:$D$195,$B46) -> 14.666667 | J46: =IF($B46=1,"",($M$4-G46)/$M$4) -> 0.94929577 | K46: =I46*$B$71 -> 58.666667 | T46: =IF($A46="Wheat",$M$7,$M$8) -> 69.333333
A47: Canola | B47: 12 | C47: Luximax + Plat | D47: Luximax 500 mL/ha | E47: Plat Xtra 360 330 mL/ha + Hasten 1% | F47: =COUNTIFS('Collated (corrected)'!$A$4:$A$195,$A47,'Collated (corrected)'!$D$4:$D$195,$B47) -> 3 | G47: =AVERAGEIFS('Collated (corrected)'!$K$4:$K$195,'Collated (corrected)'!$A$4:$A$195,$A47,'Collated (corrected)'!$D$4:$D$195,$B47) -> 65 | H47: =AVERAGEIFS('Collated (corrected)'!$H$4:$H$195,'Collated (corrected)'!$A$4:$A$195,$A47,'Collated (corrected)'!$D$4:$D$195,$B47) -> 0 | I47: =AVERAGEIFS('Collated (corrected)'!$L$4:$L$195,'Collated (corrected)'!$A$4:$A$195,$A47,'Collated (corrected)'!$D$4:$D$195,$B47) -> 13.333333 | J47: =IF($B47=1,"",($M$4-G47)/$M$4) -> 0.89014085 | K47: =I47*$B$71 -> 53.333333 | T47: =IF($A47="Wheat",$M$7,$M$8) -> 69.333333
... A67: Canola | B67: 32 | C67: TriflurX + Dual Gold | D67: TriflurX 2000 mL/ha | E67: Dual Gold 500 mL/ha | F67: =COUNTIFS('Collated (corrected)'!$A$4:$A$195,$A67,'Collated (corrected)'!$D$4:$D$195,$B67) -> 3 | G67: =AVERAGEIFS('Collated (corrected)'!$K$4:$K$195,'Collated (corrected)'!$A$4:$A$195,$A67,'Collated (corrected)'!$D$4:$D$195,$B67) -> 93.333333 | H67: =AVERAGEIFS('Collated (corrected)'!$H$4:$H$195,'Collated (corrected)'!$A$4:$A$195,$A67,'Collated (corrected)'!$D$4:$D$195,$B67) -> 8.3333333 | I67: =AVERAGEIFS('Collated (corrected)'!$L$4:$L$195,'Collated (corrected)'!$A$4:$A$195,$A67,'Collated (corrected)'!$D$4:$D$195,$B67) -> 14.666667 | J67: =IF($B67=1,"",($M$4-G67)/$M$4) -> 0.84225352 | K67: =I67*$B$71 -> 58.666667 | T67: =IF($A67="Wheat",$M$7,$M$8) -> 69.333333
A69: Assumptions & Flag Thresholds
A70: Row spacing (inches) | B70: 10
A71: Plants/m² conversion factor (approx., per 10" row spacing) | B71: 4
A72: Phytotoxicity flag threshold (%) | B72: 15
A73: Stand-loss flag threshold (% of CHK plants/m²) | B73: 0.7
A74: Red = phytotox ≥ threshold. Orange = plant stand < threshold × CHK.

Sheet Junee Canola · Phyto+Counts
A1: AGnVET Junee — Canola — Plant Establishment & Phytotox (14–28 DAA) | E1: Assessment Date: | F1: Assessor(s):
A2: 3 reps · 96 plots · 2 × 12 m · 100 L/ha
A3: Plot # | B3: Block | C3: Trt # | D3: Treatment | E3: App A (IBS) | F3: App B (EPE/Post) | G3: Phytotox % | H3: ARG Q1 | I3: ARG Q2 | J3: Plants/m | K3: Assessor | L3: Photo? | M3: Notes / Observations
A4: 101 | B4: 1 | C4: 13 | D4: Lux + Edge + Plat | E4: Luximax 500 mL/ha | F4: Edge Unify 570 g/ha + Plat 330 mL/ha | G4: 5 | H4: 4 | I4: 2 | J4: 12
A5: 102 | B5: 1 | C5: 12 | D5: Luximax + Plat | E5: Luximax 500 mL/ha | F5: Plat Xtra 360 330 mL/ha + Hasten 1% | G5: 0 | H5: 11 | I5: 4 | J5: 15
A6: 103 | B6: 1 | C6: 8 | D6: TriflurX + Plat Xtra | E6: TriflurX 2000 mL/ha | F6: Plat Xtra 360 330 mL/ha + Hasten 1% | G6: 0 | H6: 4 | I6: 4 | J6: 26
A7: 104 | B7: 1 | C7: 5 | D7: Rustler | E7: Rustler 1000 mL/ha | F7: — | G7: 0 | H7: 3 | I7: 3 | J7: 15
A8: 105 | B8: 1 | C8: 24 | D8: TriflurX + Tenet | E8: TriflurX 2000 mL/ha | F8: Tenet 1500 mL/ha | G8: 0 | H8: 1 | I8: 0 | J8: 21
A9: 106 | B9: 1 | C9: 27 | D9: TriflurX + Avadex + Atrazine | E9: TriflurX 2000 mL/ha + Avadex 2000 mL/ha | F9: Atrazine 2200 g/ha | G9: 0 | H9: 3 | I9: 2 | J9: 11
A10: 107 | B10: 1 | C10: 23 | D10: TriflurX + Rustler | E10: TriflurX 2000 mL/ha + Rustler 1000 mL/ha | F10: — | G10: 0 | H10: 3 | I10: 0 | J10: 25 | M10: Paddock variability
A11: 108 | B11: 1 | C11: 16 | D11: Lux + Devrinol + Plat | E11: Luximax 500 mL/ha | F11: Devrinol 3000 mL/ha + Plat 330 mL/ha | G11: 0 | H11: 0 | I11: 1 | J11: 26
A13: 201 | B13: 2 | C13: 29 | D13: Atrazine split dose | E13: Atrazine 1100 g/ha | F13: Atrazine 1100 g/ha | G13: 5 | H13: 14 | I13: 22 | J13: 8
A14: 202 | B14: 2 | C14: 2 | D14: Devrinol Advanced | E14: Devrinol Advanced 3000 mL/ha | F14: — | G14: 0 | H14: 10 | I14: 12 | J14: 11
A15: 203 | B15: 2 | C15: 11 | D15: Overwatch + Plat | E15: Overwatch 1250 mL/ha | F15: Plat Xtra 360 330 mL/ha + Hasten 1% | G15: 0 | H15: 2 | I15: 1 | J15: 14 | M15: Less vigour in canola
A16: 204 | B16: 2 | C16: 6 | D16: Tenet | E16: Tenet 1500 mL/ha | F16: — | G16: 0 | H16: 37 | I16: 40 | J16: 16
A17: 205 | B17: 2 | C17: 32 | D17: TriflurX + Dual Gold | E17: TriflurX 2000 mL/ha | F17: Dual Gold 500 mL/ha | G17: 0 | H17: 11 | I17: 10 | J17: 14
A18: 206 | B18: 2 | C18: 7 | D18: TriflurX | E18: TriflurX 2000 mL/ha | F18: — | G18: 0 | H18: 5 | I18: 11 | J18: 15
A19: 207 | B19: 2 | C19: 26 | D19: TriflurX + Avadex | E19: TriflurX 2000 mL/ha + Avadex 2000 mL/ha | F19: — | G19: 0 | H19: 7 | I19: 3 | J19: 14
A20: 208 | B20: 2 | C20: 3 | D20: Overwatch | E20: Overwatch 1250 mL/ha | F20: — | G20: 0 | H20: 14 | I20: 16 | J20: 14
A22: 301 | B22: 3 | C22: 31 | D22: TriflurX + Luximax (post) | E22: TriflurX 2000 mL/ha | F22: Luximax 500 mL/ha | G22: 0 | H22: 18 | I22: 12 | J22: 12
A23: 302 | B23: 3 | C23: 28 | D23: Atrazine 2200 | E23: Atrazine 2200 g/ha | F23: — | G23: 0 | H23: 37 | I23: 42 | J23: 12
A24: 303 | B24: 3 | C24: 25 | D24: Product X | E24: Product X 1500 g/ha | F24: — | G24: 0 | H24: 14 | I24: 10 | J24: 11
A25: 304 | B25: 3 | C25: 19 | D25: Lux + Tenet + Atrazine | E25: Luximax 500 mL/ha | F25: Tenet 1200 mL/ha + Atrazine 2200 g/ha + Plat 330 mL/ha | G25: 20 | H25: 9 | I25: 3 | J25: 13
A26: 305 | B26: 3 | C26: 10 | D26: Devrinol Adv + Plat | E26: Devrinol Advanced 3000 mL/ha | F26: Plat Xtra 360 330 mL/ha + Hasten 1% | G26: 0 | H26: 13 | I26: 6 | J26: 20
A27: 306 | B27: 3 | C27: 4 | D27: Luximax | E27: Luximax 500 mL/ha | F27: — | G27: 0 | H27: 16 | I27: 15 | J27: 11
A28: 307 | B28: 3 | C28: 30 | D28: TriflurX + Avadex + Plat | E28: TriflurX 2000 + Avadex 2000 mL/ha | F28: Plat 360 mL/ha + Atrazine 2200 g/ha | G28: 0 | H28: 2 | I28: 3 | J28: 14
A29: 308 | B29: 3 | C29: 21 | D29: Edge Unify | E29: — | F29: Edge Unify 570 g/ha | G29: 0 | H29: 22 | I29: 27 | J29: 11
A31: 401 | B31: 4 | C31: 9 | D31: Rustler + Plat Xtra | E31: Rustler 1000 mL/ha | F31: Plat Xtra 360 330 mL/ha + Hasten 1% | G31: 0 | H31: 12 | I31: 3 | J31: 15 | M31: Ryegrass more in between furrows
A32: 402 | B32: 4 | C32: 22 | D32: Tenet (post) | E32: — | F32: Tenet 1200 g/ha | G32: 5 | H32: 47 | I32: 32 | J32: 16
A33: 403 | B33: 4 | C33: 18 | D33: Lux + Atrazine + Edge + Plat | E33: Luximax 500 mL/ha | F33: Atrazine 2200 g/ha + Edge 570 g/ha + Plat 330 mL/ha | G33: 5 | H33: 2 | I33: 3 | J33: 14
A34: 404 | B34: 4 | C34: 15 | D34: Lux + Tenet 1200 + Plat | E34: Luximax 500 mL/ha | F34: Tenet 1200 g/ha + Plat 330 mL/ha | G34: 15 | H34: 5 | I34: 12 | J34: 15 | M34: Clethodim symptoms are evident on ryegrass
A35: 405 | B35: 4 | C35: 1 | D35: CHK | E35: — | F35: — | G35: 0 | H35: 75 | I35: 72 | J35: 14
A36: 406 | B36: 4 | C36: 14 | D36: Lux + Tenet 750 + Plat | E36: Luximax 500 mL/ha | F36: Tenet 750 mL/ha + Plat 330 mL/ha | G36: 25 | H36: 5 | I36: 6 | J36: 12
A37: 407 | B37: 4 | C37: 17 | D37: Lux + Atrazine + Plat | E37: Luximax 500 mL/ha | F37: Atrazine 2200 g/ha + Plat 330 mL/ha | G37: 10 | H37: 8 | I37: 10 | J37: 10 | M37: Less vigour in canola, surviving ryegrass is crook as
A38: 408 | B38: 4 | C38: 20 | D38: Lux + Atrazine + Tenet | E38: Luximax 500 mL/ha | F38: Atrazine 2200 g/ha + Tenet 1200 mL/ha + Plat 330 mL/ha | G38: 10 | H38: 4 | I38: 2 | J38: 20 | M38: Less vigour in canola, surviving ryegrass is crook as
A40: 501 | B40: 5 | C40: 7 | D40: TriflurX | E40: TriflurX 2000 mL/ha | F40: — | G40: 0 | H40: 16 | I40: 17 | J40: 12
A41: 502 | B41: 5 | C41: 11 | D41: Overwatch + Plat | E41: Overwatch 1250 mL/ha | F41: Plat Xtra 360 330 mL/ha + Hasten 1% | G41: 5 | H41: 3 | I41: 6 | J41: 14
A42: 503 | B42: 5 | C42: 8 | D42: TriflurX + Plat Xtra | E42: TriflurX 2000 mL/ha | F42: Plat Xtra 360 330 mL/ha + Hasten 1% | G42: 0 | H42: 7 | I42: 8 | J42: 14
A43: 504 | B43: 5 | C43: 21 | D43: Edge Unify | E43: — | F43: Edge Unify 570 g/ha | G43: 0 | H43: 19 | I43: 17 | J43: 13
A44: 505 | B44: 5 | C44: 12 | D44: Luximax + Plat | E44: Luximax 500 mL/ha | F44: Plat Xtra 360 330 mL/ha + Hasten 1% | G44: 0 | H44: 8 | I44: 7 | J44: 15
...

Sheet Junee Canola · Count 2
A1: AGnVET Junee — Canola — Ryegrass Count 2 | G1: Assessment date: | I1: Assessor(s):
A2: 3 reps · 96 plots · 2 × 12 m · 100 L/ha · treatments ARM-validated (Aglink Canola Pre-em Junee tour report, Jun-1-2026)
A3: Plot # | B3: Block | C3: Trt # | D3: Treatment | E3: App A (IBS) | F3: App B (EPE/Post) | G3: ARG Q1 | H3: ARG Q2 | I3: Ryegrass /m² | J3: Phytotox % (opt.) | K3: Assessor | L3: Photo? | M3: Notes / Observations | N3: C1 RG /m² | O3: Δ vs C1
A4: 101 | B4: 1 | C4: 13 | D4: Lux + Edge + Plat | E4: Luximax 500 mL/ha | F4: Edge Unify 570 g/ha + Plat 330 mL/ha | I4: =IF(COUNT(G4:H4)=2,(G4+H4)*5,"") | N4: =('Junee Canola · Phyto+Counts'!H4+'Junee Canola · Phyto+Counts'!I4)*5 -> 30 | O4: =IF(I4="","",I4-N4)
A5: 102 | B5: 1 | C5: 12 | D5: Luximax + Plat | E5: Luximax 500 mL/ha | F5: Plat Xtra 360 330 mL/ha + Hasten 1% | I5: =IF(COUNT(G5:H5)=2,(G5+H5)*5,"") | N5: =('Junee Canola · Phyto+Counts'!H5+'Junee Canola · Phyto+Counts'!I5)*5 -> 75 | O5: =IF(I5="","",I5-N5)
A6: 103 | B6: 1 | C6: 8 | D6: TriflurX + Plat Xtra | E6: TriflurX 2000 mL/ha | F6: Plat Xtra 360 330 mL/ha + Hasten 1% | I6: =IF(COUNT(G6:H6)=2,(G6+H6)*5,"") | N6: =('Junee Canola · Phyto+Counts'!H6+'Junee Canola · Phyto+Counts'!I6)*5 -> 40 | O6: =IF(I6="","",I6-N6)
A7: 104 | B7: 1 | C7: 5 | D7: Rustler | E7: Rustler 1000 mL/ha | F7: — | I7: =IF(COUNT(G7:H7)=2,(G7+H7)*5,"") | N7: =('Junee Canola · Phyto+Counts'!H7+'Junee Canola · Phyto+Counts'!I7)*5 -> 30 | O7: =IF(I7="","",I7-N7)
A8: 105 | B8: 1 | C8: 24 | D8: TriflurX + Tenet | E8: TriflurX 2000 mL/ha | F8: Tenet 1500 mL/ha | I8: =IF(COUNT(G8:H8)=2,(G8+H8)*5,"") | N8: =('Junee Canola · Phyto+Counts'!H8+'Junee Canola · Phyto+Counts'!I8)*5 -> 5 | O8: =IF(I8="","",I8-N8)
A9: 106 | B9: 1 | C9: 27 | D9: TriflurX + Avadex + Atrazine | E9: TriflurX 2000 mL/ha + Avadex 2000 mL/ha | F9: Atrazine 2200 g/ha | I9: =IF(COUNT(G9:H9)=2,(G9+H9)*5,"") | N9: =('Junee Canola · Phyto+Counts'!H9+'Junee Canola · Phyto+Counts'!I9)*5 -> 25 | O9: =IF(I9="","",I9-N9)
A10: 107 | B10: 1 | C10: 23 | D10: TriflurX + Rustler | E10: TriflurX 2000 mL/ha + Rustler 1000 mL/ha | F10: — | I10: =IF(COUNT(G10:H10)=2,(G10+H10)*5,"") | N10: =('Junee Canola · Phyto+Counts'!H10+'Junee Canola · Phyto+Counts'!I10)*5 -> 15 | O10: =IF(I10="","",I10-N10)
A11: 108 | B11: 1 | C11: 16 | D11: Lux + Devrinol + Plat | E11: Luximax 500 mL/ha | F11: Devrinol 3000 mL/ha + Plat 330 mL/ha | I11: =IF(COUNT(G11:H11)=2,(G11+H11)*5,"") | N11: =('Junee Canola · Phyto+Counts'!H11+'Junee Canola · Phyto+Counts'!I11)*5 -> 5 | O11: =IF(I11="","",I11-N11)
A13: 201 | B13: 2 | C13: 29 | D13: Atrazine split dose | E13: Atrazine 1100 g/ha | F13: Atrazine 1100 g/ha | I13: =IF(COUNT(G13:H13)=2,(G13+H13)*5,"") | N13: =('Junee Canola · Phyto+Counts'!H13+'Junee Canola · Phyto+Counts'!I13)*5 -> 180 | O13: =IF(I13="","",I13-N13)
A14: 202 | B14: 2 | C14: 2 | D14: Devrinol Advanced | E14: Devrinol Advanced 3000 mL/ha | F14: — | I14: =IF(COUNT(G14:H14)=2,(G14+H14)*5,"") | N14: =('Junee Canola · Phyto+Counts'!H14+'Junee Canola · Phyto+Counts'!I14)*5 -> 110 | O14: =IF(I14="","",I14-N14)
A15: 203 | B15: 2 | C15: 11 | D15: Overwatch + Plat | E15: Overwatch 1250 mL/ha | F15: Plat Xtra 360 330 mL/ha + Hasten 1% | I15: =IF(COUNT(G15:H15)=2,(G15+H15)*5,"") | N15: =('Junee Canola · Phyto+Counts'!H15+'Junee Canola · Phyto+Counts'!I15)*5 -> 15 | O15: =IF(I15="","",I15-N15)
A16: 204 | B16: 2 | C16: 6 | D16: Tenet | E16: Tenet 1500 mL/ha | F16: — | I16: =IF(COUNT(G16:H16)=2,(G16+H16)*5,"") | N16: =('Junee Canola · Phyto+Counts'!H16+'Junee Canola · Phyto+Counts'!I16)*5 -> 385 | O16: =IF(I16="","",I16-N16)
... A110: 1208 | B110: 12 | C110: 13 | D110: Lux + Edge + Plat | E110: Luximax 500 mL/ha | F110: Edge Unify 570 g/ha + Plat 330 mL/ha | I110: =IF(COUNT(G110:H110)=2,(G110+H110)*5,"") | N110: =('Junee Canola · Phyto+Counts'!H110+'Junee Canola · Phyto+Counts'!I110)*5 -> 75 | O110: =IF(I110="","",I110-N110)
A112: ★ Enter ARG Q1 and ARG Q2 only (cream cells) — 2 × 0.1 m² quadrats per plot, ryegrass plants counted. Ryegrass /m² auto = (Q1 + Q2) × 5. Phytotox % is optional (0–100, crop effect). Photo: Y / N. Green rows = untreated control (CHK). Grey columns are read-only: C1 RG /m² and Δ pull from the Count 1 sheet — plot numbers and treatments are ARM-validated, do not edit columns A–F in the field.

Sheet Junee Wheat · Phyto+Counts
A1: AGnVET Junee — Wheat — Plant Establishment & Phytotox (14–28 DAA) | E1: Assessment Date: | F1: Assessor(s):
A2: 3 reps · 96 plots · 12 × 2 m · 200 L/ha
A3: Plot # | B3: Block | C3: Trt # | D3: Treatment | E3: App A (IBS) | F3: App B (EPE/Post) | G3: Phytotox % | H3: ARG Q1 | I3: ARG Q2 | J3: Plants/m | K3: Assessor | L3: Photo? | M3: Notes / Observations
A4: 101 | B4: 1 | C4: 7 | D4: Spruce | E4: Spruce 500 mL/ha | F4: — | G4: 5 | H4: 16 | I4: 25 | J4: 42
A5: 102 | B5: 1 | C5: 27 | D5: Mateno Complete (post) | E5: — | F5: Mateno Complete 1000 mL/ha | G5: 10 | H5: 42 | I5: 24 | J5: 25
A6: 103 | B6: 1 | C6: 24 | D6: Overwatch (post) | E6: — | F6: Overwatch 1250 mL/ha | G6: 70 | H6: 24 | I6: 32 | J6: 28
A7: 104 | B7: 1 | C7: 17 | D7: TriflurX + Syrexon 1700 | E7: TriflurX 2000 mL/ha | F7: Syrexon 1700 mL/ha | G7: 50 | H7: 12 | I7: 7 | J7: 32
A8: 105 | B8: 1 | C8: 11 | D8: Voraxor + Sakura | E8: Voraxor 200 mL/ha + Sakura 118 g/ha | F8: — | G8: 5 | H8: 28 | I8: 28 | J8: 37
A9: 106 | B9: 1 | C9: 20 | D9: TriflurX + Mateno | E9: TriflurX 2000 mL/ha | F9: Mateno Complete 1000 mL/ha | G9: 0 | H9: 6 | I9: 7 | J9: 33
A10: 107 | B10: 1 | C10: 31 | D10: TriflurX + Avadex + Boxer | E10: TriflurX 2000 mL/ha + Avadex 2000 mL/ha | F10: Boxer Gold 3000 mL/ha | G10: 5 | H10: 8 | I10: 6 | J10: 28
A11: 108 | B11: 1 | C11: 22 | D11: Avadex | E11: Avadex 2000 mL/ha | F11: — | G11: 0 | H11: 17 | I11: 25 | J11: 38
A13: 201 | B13: 2 | C13: 26 | D13: Terrain Flow + Sakura | E13: Terrain Flow 125 mL/ha + Sakura 118 g/ha | F13: — | G13: 5 | H13: 20 | I13: 28 | J13: 42
A14: 202 | B14: 2 | C14: 29 | D14: Overwatch + Sakura (post) | E14: Overwatch 1250 mL/ha + Sakura 118 g/ha | F14: — | G14: 15 | H14: 20 | I14: 32 | J14: 32
A15: 203 | B15: 2 | C15: 21 | D15: TriflurX + Avadex | E15: TriflurX 2000 mL/ha + Avadex 2000 mL/ha | F15: — | G15: 0 | H15: 12 | I15: 8 | J15: 27
A16: 204 | B16: 2 | C16: 15 | D16: Sakura + Syrexon 1300 | E16: Sakura 118 g/ha | F16: Syrexon 1300 mL/ha | G16: 15 | H16: 15 | I16: 20 | J16: 32
... A33: 403 | B33: 4 | C33: 32 | D33: Terrain Flow + Sakura (2) | E33: Terrain Flow 125 mL/ha + Sakura 118 g/ha | F33: — | G33: 5 | H33: 11 | I33: 15 | J33: 32
A34: 404 | B34: 4 | C34: 4 | D34: Luximax | E34: Luximax 500 mL/ha | F34: — | G34: 0 | H34: 10 | I34: 10 | J34: 28 | M34: Damage where boom was primed
A35: 405 | B35: 4 | C35: 19 | D35: Overwatch + Boxer Gold | E35: Overwatch 1250 mL/ha | F35: Boxer Gold 2500 mL/ha | G35: 10 | H35: 22 | I35: 25 | J35: 42
A36: 406 | B36: 4 | C36: 1 | D36: CHK | E36: — | F36: — | G36: 0 | H36: 102 | I36: 104 | J36: 32 | M36: Denser ryegrass than neighbouring treatment, suspicion of being an untreated control (labelled 1)
A37: 407 | B37: 4 | C37: 16 | D37: Sakura + Syrexon 1700 | E37: Sakura 118 g/ha | F37: Syrexon 1700 mL/ha | G37: 50 | H37: 15 | I37: 18 | J37: 42
A38: 408 | B38: 4 | C38: 28 | D38: Sakura + Brodal | E38: — | F38: Sakura 118 g/ha + Brodal 132 mL/ha | G38: 30 | H38: 8 | I38: 32 | J38: 28
A40: 501 | B40: 5 | C40: 12 | D40: Voraxor + Spruce | E40: Voraxor 200 mL/ha + Spruce 500 mL/ha | F40: — | G40: 5 | H40: 10 | I40: 8 | J40: 27
A41: 502 | B41: 5 | C41: 21 | D41: TriflurX + Avadex | E41: TriflurX 2000 mL/ha + Avadex 2000 mL/ha | F41: — | G41: 0 | H41: 10 | I41: 12 | J41: 35
A42: 503 | B42: 5 | C42: 6 | D42: Sakura | E42: Sakura 118 g/ha | F42: — | G42: 0 | H42: 13 | I42: 10 | J42: 42
A43: 504 | B43: 5 | C43: 25 | D43: Arcade + Mateno | E43: Arcade 3000 mL/ha | F43: Mateno Complete 1000 mL/ha | G43: 5 | H43: 15 | I43: 28 | J43: 28
A44: 505 | B44: 5 | C44: 23 | D44: TriflurX + Avadex + Mateno | E44: TriflurX 2000 mL/ha + Avadex 2000 mL/ha | F44: Mateno Complete 1000 mL/ha | G44: 15 | H44: 8 | I44: 20 | J44: 32
A45: 506 | B45: 5 | C45: 24 | D45: Overwatch (post) | E45: — | F45: Overwatch 1250 mL/ha | G45: 70 | H45: 35 | I45: 15 | J45: 44
A46: 507 | B46: 5 | C46: 18 | D46: Overwatch + Mateno | E46: Overwatch 1250 mL/ha | F46: Mateno Complete 1000 mL/ha | G46: 15 | H46: 12 | I46: 22 | J46: 28
A47: 508 | B47: 5 | C47: 29 | D47: Overwatch + Sakura (post) | E47: Overwatch 1250 mL/ha + Sakura 118 g/ha | F47: — | G47: 5 | H47: 44 | I47: 33 | J47: 32 | M47: Large ryegrass numbers
A49: 601 | B49: 6 | C49: 17 | D49: TriflurX + Syrexon 1700 | E49: TriflurX 2000 mL/ha | F49: Syrexon 1700 mL/ha | G49: 60 | H49: 34 | I49: 27 | J49: 23 | M49: Bleached ryegrass
A50: 602 | B50: 6 | C50: 1 | D50: CHK | E50: — | F50: — | G50: 0 | H50: 36 | I50: 53 | J50: 23
A51: 603 | B51: 6 | C51: 32 | D51: Terrain Flow + Sakura (2) | E51: Terrain Flow 125 mL/ha + Sakura 118 g/ha | F51: — | G51: 0 | H51: 19 | I51: 19 | J51: 16
A52: 604 | B52: 6 | C52: 10 | D52: Overwatch + Spruce | E52: Overwatch 1250 mL/ha + Spruce 500 mL/ha | F52: — | G52: 0 | H52: 7 | I52: 8 | J52: 24
A53: 605 | B53: 6 | C53: 30 | D53: Sakura split dose | E53: Sakura 100 g/ha | F53: Sakura 30 g/ha | G53: 0 | H53: 16 | I53: 22 | J53: 20
A54: 606 | B54: 6 | C54: 11 | D54: Voraxor + Sakura | E54: Voraxor 200 mL/ha + Sakura 118 g/ha | F54: — | G54: 0 | H54: 18 | I54: 16 | J54: 16
A55: 607 | B55: 6 | C55: 14 | D55: Spruce + Avadex | E55: Spruce 500 mL/ha + Avadex 2000 mL/ha | F55: — | G55: 0 | H55: 25 | I55: 20 | J55: 25
A56: 608 | B56: 6 | C56: 5 | D56: Overwatch | E56: Overwatch 1250 mL/ha | F56: — | G56: 5 | H56: 28 | I56: 22 | J56: 28
A58: 701 | B58: 7 | C58: 16 | D58: Sakura + Syrexon 1700 | E58: Sakura 118 g/ha | F58: Syrexon 1700 mL/ha | G58: 60 | H58: 28 | I58: 7 | J58: 25
A59: 702 | B59: 7 | C59: 22 | D59: Avadex | E59: Avadex 2000 mL/ha | F59: — | G59: 0 | H59: 11 | I59: 6 | J59: 24
A60: 703 | B60: 7 | C60: 31 | D60: TriflurX + Avadex + Boxer | E60: TriflurX 2000 mL/ha + Avadex 2000 mL/ha | F60: Boxer Gold 3000 mL/ha | G60: 0 | H60: 5 | I60: 6 | J60: 16
...

Sheet Junee Wheat · Count 2
A1: AGnVET Junee — Wheat — Ryegrass Count 2 | G1: Assessment date: | I1: Assessor(s):
A2: 3 reps · 96 plots · 12 × 2 m · treatments ARM-validated (Wheat Pre-em Junee map, May-14-2026)
A3: Plot # | B3: Block | C3: Trt # | D3: Treatment | E3: App A (IBS) | F3: App B (EPE/Post) | G3: ARG Q1 | H3: ARG Q2 | I3: Ryegrass /m² | J3: Phytotox % (opt.) | K3: Assessor | L3: Photo? | M3: Notes / Observations | N3: C1 RG /m² | O3: Δ vs C1
A4: 101 | B4: 1 | C4: 7 | D4: Spruce | E4: Spruce 500 mL/ha | F4: — | I4: =IF(COUNT(G4:H4)=2,(G4+H4)*5,"") | N4: =('Junee Wheat · Phyto+Counts'!H4+'Junee Wheat · Phyto+Counts'!I4)*5 -> 205 | O4: =IF(I4="","",I4-N4)
A5: 102 | B5: 1 | C5: 27 | D5: Mateno Complete (post) | E5: — | F5: Mateno Complete 1000 mL/ha | I5: =IF(COUNT(G5:H5)=2,(G5+H5)*5,"") | N5: =('Junee Wheat · Phyto+Counts'!H5+'Junee Wheat · Phyto+Counts'!I5)*5 -> 330 | O5: =IF(I5="","",I5-N5)
A6: 103 | B6: 1 | C6: 24 | D6: Overwatch (post) | E6: — | F6: Overwatch 1250 mL/ha | I6: =IF(COUNT(G6:H6)=2,(G6+H6)*5,"") | N6: =('Junee Wheat · Phyto+Counts'!H6+'Junee Wheat · Phyto+Counts'!I6)*5 -> 280 | O6: =IF(I6="","",I6-N6)
A7: 104 | B7: 1 | C7: 17 | D7: TriflurX + Syrexon 1700 | E7: TriflurX 2000 mL/ha | F7: Syrexon 1700 mL/ha | I7: =IF(COUNT(G7:H7)=2,(G7+H7)*5,"") | N7: =('Junee Wheat · Phyto+Counts'!H7+'Junee Wheat · Phyto+Counts'!I7)*5 -> 95 | O7: =IF(I7="","",I7-N7)
A8: 105 | B8: 1 | C8: 11 | D8: Voraxor + Sakura | E8: Voraxor 200 mL/ha + Sakura 118 g/ha | F8: — | I8: =IF(COUNT(G8:H8)=2,(G8+H8)*5,"") | N8: =('Junee Wheat · Phyto+Counts'!H8+'Junee Wheat · Phyto+Counts'!I8)*5 -> 280 | O8: =IF(I8="","",I8-N8)
A9: 106 | B9: 1 | C9: 20 | D9: TriflurX + Mateno | E9: TriflurX 2000 mL/ha | F9: Mateno Complete 1000 mL/ha | I9: =IF(COUNT(G9:H9)=2,(G9+H9)*5,"") | N9: =('Junee Wheat · Phyto+Counts'!H9+'Junee Wheat · Phyto+Counts'!I9)*5 -> 65 | O9: =IF(I9="","",I9-N9)
A10: 107 | B10: 1 | C10: 31 | D10: TriflurX + Avadex + Boxer | E10: TriflurX 2000 mL/ha + Avadex 2000 mL/ha | F10: Boxer Gold 3000 mL/ha | I10: =IF(COUNT(G10:H10)=2,(G10+H10)*5,"") | N10: =('Junee Wheat · Phyto+Counts'!H10+'Junee Wheat · Phyto+Counts'!I10)*5 -> 70 | O10: =IF(I10="","",I10-N10)
A11: 108 | B11: 1 | C11: 22 | D11: Avadex | E11: Avadex 2000 mL/ha | F11: — | I11: =IF(COUNT(G11:H11)=2,(G11+H11)*5,"") | N11: =('Junee Wheat · Phyto+Counts'!H11+'Junee Wheat · Phyto+Counts'!I11)*5 -> 210 | O11: =IF(I11="","",I11-N11)
A13: 201 | B13: 2 | C13: 26 | D13: Terrain Flow + Sakura | E13: Terrain Flow 125 mL/ha + Sakura 118 g/ha | F13: — | I13: =IF(COUNT(G13:H13)=2,(G13+H13)*5,"") | N13: =('Junee Wheat · Phyto+Counts'!H13+'Junee Wheat · Phyto+Counts'!I13)*5 -> 240 | O13: =IF(I13="","",I13-N13)
A14: 202 | B14: 2 | C14: 29 | D14: Overwatch + Sakura (post) | E14: Overwatch 1250 mL/ha + Sakura 118 g/ha | F14: — | I14: =IF(COUNT(G14:H14)=2,(G14+H14)*5,"") | N14: =('Junee Wheat · Phyto+Counts'!H14+'Junee Wheat · Phyto+Counts'!I14)*5 -> 260 | O14: =IF(I14="","",I14-N14)
A15: 203 | B15: 2 | C15: 21 | D15: TriflurX + Avadex | E15: TriflurX 2000 mL/ha + Avadex 2000 mL/ha | F15: — | I15: =IF(COUNT(G15:H15)=2,(G15+H15)*5,"") | N15: =('Junee Wheat · Phyto+Counts'!H15+'Junee Wheat · Phyto+Counts'!I15)*5 -> 100 | O15: =IF(I15="","",I15-N15)
A16: 204 | B16: 2 | C16: 15 | D16: Sakura + Syrexon 1300 | E16: Sakura 118 g/ha | F16: Syrexon 1300 mL/ha | I16: =IF(COUNT(G16:H16)=2,(G16+H16)*5,"") | N16: =('Junee Wheat · Phyto+Counts'!H16+'Junee Wheat · Phyto+Counts'!I16)*5 -> 175 | O16: =IF(I16="","",I16-N16)
... A110: 1208 | B110: 12 | C110: 17 | D110: TriflurX + Syrexon 1700 | E110: TriflurX 2000 mL/ha | F110: Syrexon 1700 mL/ha | I110: =IF(COUNT(G110:H110)=2,(G110+H110)*5,"") | N110: =('Junee Wheat · Phyto+Counts'!H110+'Junee Wheat · Phyto+Counts'!I110)*5 -> 150 | O110: =IF(I110="","",I110-N110)
A112: ★ Enter ARG Q1 and ARG Q2 only (cream cells) — 2 × 0.1 m² quadrats per plot, ryegrass plants counted. Ryegrass /m² auto = (Q1 + Q2) × 5. Phytotox % is optional (0–100, crop effect). Photo: Y / N. Green rows = untreated control (CHK). Grey columns are read-only: C1 RG /m² and Δ pull from the Count 1 sheet — plot numbers and treatments are ARM-validated, do not edit columns A–F in the field.

Sheet Correction Log
A1: Wheat treatment-label corrections — validated against ARM 2025.5 Trial Map (May-14-2026)
A3: Plot # | B3: Was Trt # | C3: Was labelled | D3: Corrected Trt # | E3: Corrected treatment | F3: Source
A4: 207 | B4: 22 | C4: Avadex | D4: 23 | E4: TriflurX + Avadex + Mateno | F4: ARM tour report
A5: 406 | B5: 16 | C5: Sakura + Syrexon 1700 | D5: 1 | E5: CHK | F5: ARM tour report
A6: 504 | B6: 23 | C6: TriflurX + Avadex + Mateno | D6: 25 | E6: Arcade + Mateno | F6: ARM tour report
A7: 505 | B7: 24 | C7: Overwatch (post) | D7: 23 | E7: TriflurX + Avadex + Mateno | F7: ARM tour report
A8: 506 | B8: 18 | C8: Overwatch + Mateno | D8: 24 | E8: Overwatch (post) | F8: ARM tour report
A9: 507 | B9: 3 | C9: TriflurX | D9: 18 | E9: Overwatch + Mateno | F9: ARM tour report
A10: 705 | B10: 13 | C10: Sakura + Avadex | D10: 26 | E10: Terrain Flow + Sakura | F10: ARM tour report
A11: 805 | B11: 7 | C11: Spruce | D11: 13 | E11: Sakura + Avadex | F11: ARM tour report
A12: 905 | B12: 6 | C12: Sakura | D12: 7 | E12: Spruce | F12: ARM tour report
A13: 1005 | B13: 12 | C13: Voraxor + Spruce | D13: 6 | E13: Sakura | F13: ARM tour report
A14: 1105 | B14: 26 | C14: Terrain Flow + Sakura | D14: 12 | E14: Voraxor + Spruce | F14: ARM tour report
A15: 1205 | B15: 20 | C15: TriflurX + Mateno | D15: 26 | E15: Terrain Flow + Sakura | F15: ARM tour report
A16: 602 | B16: 1 | C16: CHK (plot # was blank) | D16: 1 | E16: CHK | F16: ARM tour report — plot number restored
A18: CANOLA treatment-label corrections — validated against ARM 2025.5 Tour Report (Jun-1-2026)
A19: Plot # | B19: Was Trt # | C19: Was labelled | D19: Corrected Trt # | E19: Corrected treatment | F19: Source
A20: 703 | B20: 23 | C20: TriflurX + Rustler | D20: 28 | E20: Atrazine 2200 | F20: ARM tour report (Jun-1-2026)
A21: 803 | B21: 15 | C21: Lux + Tenet 1200 + Plat | D21: 23 | E21: TriflurX + Rustler | F21: ARM tour report (Jun-1-2026)
A22: 1101 | B22: 19 | C22: Lux + Tenet + Atrazine | D22: 16 | E22: Lux + Devrinol + Plat | F22: ARM tour report (Jun-1-2026)
A23: 1106 | B23: 21 | C23: Edge Unify | D23: 26 | E23: TriflurX + Avadex | F23: ARM tour report (Jun-1-2026)
A25: Note: Trt 23 had correct count (3) but wrong members — plot 703 carried its label while true plot 803 sat under Trt 15. Count checks miss this; ARM is authoritative.

Sheet Chart Data
A1: Ryegrass Control — chart feeder data (auto-sorted by % control; flagged where phytotox ≥ threshold in Treatment Data!B72)
A3: Treatment | B3: % RG Control | C3: Phyto % | D3: Flag | F3: Treatment | G3: % RG Control | H3: Phyto % | I3: Flag | K3: w_Treatment | L3: w_%Ctrl | M3: w_Phyto | N3: w_Rank | P3: c_Treatment | Q3: c_%Ctrl | R3: c_Phyto | S3: c_Rank
A4: =INDEX($K$4:$K$34,MATCH(ROW()-3,$N$4:$N$34,0)) -> Overwatch + Sakura (post) | B4: =INDEX($L$4:$L$34,MATCH(ROW()-3,$N$4:$N$34,0)) -> 0.46865672 | C4: =INDEX($M$4:$M$34,MATCH(ROW()-3,$N$4:$N$34,0)) -> 6.6666667 | D4: =IF(C4>='Treatment Data'!$B$72,"High phyto","") | F4: =INDEX($P$4:$P$34,MATCH(ROW()-3,$S$4:$S$34,0)) -> Tenet (post) | G4: =INDEX($Q$4:$Q$34,MATCH(ROW()-3,$S$4:$S$34,0)) -> 0.47887324 | H4: =INDEX($R$4:$R$34,MATCH(ROW()-3,$S$4:$S$34,0)) -> 8.3333333 | I4: =IF(H4>='Treatment Data'!$B$72,"High phyto","") | K4: ='Treatment Data'!C5 -> Boxer Gold | L4: ='Treatment Data'!J5 -> 0.79701493 | M4: ='Treatment Data'!H5 -> 1.6666667 | N4: =_xlfn.RANK.EQ(L4,$L$4:$L$34,1)+COUNTIF($L$4:L4,L4)-1 -> 21 | P4: ='Treatment Data'!C37 -> Devrinol Advanced | Q4: ='Treatment Data'!J37 -> 0.72394366 | R4: ='Treatment Data'!H37 -> 0 | S4: =_xlfn.RANK.EQ(Q4,$Q$4:$Q$34,1)+COUNTIF($Q$4:Q4,Q4)-1 -> 7
A5: =INDEX($K$4:$K$34,MATCH(ROW()-3,$N$4:$N$34,0)) -> Overwatch (post) | B5: =INDEX($L$4:$L$34,MATCH(ROW()-3,$N$4:$N$34,0)) -> 0.51044776 | C5: =INDEX($M$4:$M$34,MATCH(ROW()-3,$N$4:$N$34,0)) -> 73.333333 | D5: =IF(C5>='Treatment Data'!$B$72,"High phyto","") -> High phyto | F5: =INDEX($P$4:$P$34,MATCH(ROW()-3,$S$4:$S$34,0)) -> Atrazine 2200 | G5: =INDEX($Q$4:$Q$34,MATCH(ROW()-3,$S$4:$S$34,0)) -> 0.50704225 | H5: =INDEX($R$4:$R$34,MATCH(ROW()-3,$S$4:$S$34,0)) -> 3.3333333 | I5: =IF(H5>='Treatment Data'!$B$72,"High phyto","") | K5: ='Treatment Data'!C6 -> TriflurX | L5: ='Treatment Data'!J6 -> 0.79701493 | M5: ='Treatment Data'!H6 -> 0 | N5: =_xlfn.RANK.EQ(L5,$L$4:$L$34,1)+COUNTIF($L$4:L5,L5)-1 -> 22 | P5: ='Treatment Data'!C38 -> Overwatch | Q5: ='Treatment Data'!J38 -> 0.69577465 | R5: ='Treatment Data'!H38 -> 0 | S5: =_xlfn.RANK.EQ(Q5,$Q$4:$Q$34,1)+COUNTIF($Q$4:Q5,Q5)-1 -> 6
A6: =INDEX($K$4:$K$34,MATCH(ROW()-3,$N$4:$N$34,0)) -> Sakura + Brodal | B6: =INDEX($L$4:$L$34,MATCH(ROW()-3,$N$4:$N$34,0)) -> 0.53731343 | C6: =INDEX($M$4:$M$34,MATCH(ROW()-3,$N$4:$N$34,0)) -> 15 | D6: =IF(C6>='Treatment Data'!$B$72,"High phyto","") -> High phyto | F6: =INDEX($P$4:$P$34,MATCH(ROW()-3,$S$4:$S$34,0)) -> Edge Unify | G6: =INDEX($Q$4:$Q$34,MATCH(ROW()-3,$S$4:$S$34,0)) -> 0.57746479 | H6: =INDEX($R$4:$R$34,MATCH(ROW()-3,$S$4:$S$34,0)) -> 0 | I6: =IF(H6>='Treatment Data'!$B$72,"High phyto","") | K6: ='Treatment Data'!C7 -> Luximax | L6: ='Treatment Data'!J7 -> 0.80298507 | M6: ='Treatment Data'!H7 -> 2 | N6: =_xlfn.RANK.EQ(L6,$L$4:$L$34,1)+COUNTIF($L$4:L6,L6)-1 -> 24 | P6: ='Treatment Data'!C39 -> Luximax | Q6: ='Treatment Data'!J39 -> 0.75211268 | R6: ='Treatment Data'!H39 -> 0 | S6: =_xlfn.RANK.EQ(Q6,$Q$4:$Q$34,1)+COUNTIF($Q$4:Q6,Q6)-1 -> 8
A7: =INDEX($K$4:$K$34,MATCH(ROW()-3,$N$4:$N$34,0)) -> Mateno Complete (post) | B7: =INDEX($L$4:$L$34,MATCH(ROW()-3,$N$4:$N$34,0)) -> 0.64776119 | C7: =INDEX($M$4:$M$34,MATCH(ROW()-3,$N$4:$N$34,0)) -> 3.3333333 | D7: =IF(C7>='Treatment Data'!$B$72,"High phyto","") | F7: =INDEX($P$4:$P$34,MATCH(ROW()-3,$S$4:$S$34,0)) -> Tenet | G7: =INDEX($Q$4:$Q$34,MATCH(ROW()-3,$S$4:$S$34,0)) -> 0.65633803 | H7: =INDEX($R$4:$R$34,MATCH(ROW()-3,$S$4:$S$34,0)) -> 0 | I7: =IF(H7>='Treatment Data'!$B$72,"High phyto","") | K7: ='Treatment Data'!C8 -> Overwatch | L7: ='Treatment Data'!J8 -> 0.65671642 | M7: ='Treatment Data'!H8 -> 3.3333333 | N7: =_xlfn.RANK.EQ(L7,$L$4:$L$34,1)+COUNTIF($L$4:L7,L7)-1 -> 5 | P7: ='Treatment Data'!C40 -> Rustler | Q7: ='Treatment Data'!J40 -> 0.83380282 | R7: ='Treatment Data'!H40 -> 0 | S7: =_xlfn.RANK.EQ(Q7,$Q$4:$Q$34,1)+COUNTIF($Q$4:Q7,Q7)-1 -> 12
A8: =INDEX($K$4:$K$34,MATCH(ROW()-3,$N$4:$N$34,0)) -> Overwatch | B8: =INDEX($L$4:$L$34,MATCH(ROW()-3,$N$4:$N$34,0)) -> 0.65671642 | C8: =INDEX($M$4:$M$34,MATCH(ROW()-3,$N$4:$N$34,0)) -> 3.3333333 | D8: =IF(C8>='Treatment Data'!$B$72,"High phyto","") | F8: =INDEX($P$4:$P$34,MATCH(ROW()-3,$S$4:$S$34,0)) -> Atrazine split dose | G8: =INDEX($Q$4:$Q$34,MATCH(ROW()-3,$S$4:$S$34,0)) -> 0.67887324 | H8: =INDEX($R$4:$R$34,MATCH(ROW()-3,$S$4:$S$34,0)) -> 3.3333333 | I8: =IF(H8>='Treatment Data'!$B$72,"High phyto","") | K8: ='Treatment Data'!C9 -> Sakura | L8: ='Treatment Data'!J9 -> 0.71044776 | M8: ='Treatment Data'!H9 -> 0 | N8: =_xlfn.RANK.EQ(L8,$L$4:$L$34,1)+COUNTIF($L$4:L8,L8)-1 -> 13 | P8: ='Treatment Data'!C41 -> Tenet | Q8: ='Treatment Data'!J41 -> 0.65633803 | R8: ='Treatment Data'!H41 -> 0 | S8: =_xlfn.RANK.EQ(Q8,$Q$4:$Q$34,1)+COUNTIF($Q$4:Q8,Q8)-1 -> 4
