Workbook

Sheet Inputs
A1: AGnVET Services — IK Caldwell
A2: 2026 Fungicide Trials — Ringwood — Mixing Plan
A4: Parameter | B4: Value | C4: Unit | D4: Basis
A5: Plot width | B5: 2 | C5: m | D5: Trial spec
A6: Plot length | B6: 12 | C6: m | D6: Trial spec
A7: Plot area | B7: =B5*B6 -> 24 | C7: m² | D7: width × length
A8: Replicates | B8: 3 | C8: no. | D8: Ringwood wheat — 3 reps (68 clean plots, 4 marginals used)
A9: Water rate | B9: 100 | C9: L/ha | D9: Trial spec
A10: Water required per plot | B10: =B7/10000*B9 -> 0.24 | C10: L | D10: plot area ÷ 10,000 × water rate
A11: Water required per treatment | B11: =B10*B8 -> 0.72 | C11: L | D11: per plot × replicates
A12: Overage per batch | B12: 0.54 | C12: L | D12: Priming / dead volume — adjust to suit sprayer
A13: BATCH VOLUME PER TREATMENT | B13: =B11+B12 -> 1.26 | C13: L | D13: required + overage. Drives every ml figure.
A15: Legend
A16: Yellow / blue cells are inputs — change these only. Everything else is a formula.
A17: Rates entered as ml/ha, g/ha or % v/v. Adjuvant % is v/v of the batch volume.
A18: Measure product with graduated syringes. Anything under 3 ml — make a 10× stock dilution and draw 10× the volume.
A19: Replicates is set to 3 for Ringwood (wheat only). Set to 4 to match Matong batch sizes, or 7 for one mix covering both sites.
A20: Site agronomy, growth stages and layout: see the 2026 Fungicide Trials Site Information Sheet.

Sheet Wheat Mixing
A1: AGnVET Services — IK Caldwell
A2: Wheat Fungicide Trial — Ringwood (Corowa) — Mixing Plan (rev. C, 24 treatments)
A3: Batch volume per treatment (L): | D3: =Inputs!B13 -> 1.26 | E3: Water per plot (L): | F3: =Inputs!B10 -> 0.24
A5: Trt | B5: Treatment | C5: Timing | D5: Product | E5: Rate | F5: Unit | G5: Per batch (ml) | H5: Check
A6: 1 | B6: Untreated | C6: A | D6: Water only | H6: ☐
A7: 2 | B7: Aviator Xpro | C7: A | D7: Aviator Xpro | E7: 500 | F7: ml/ha | G7: =IF(F7="% v/v",$D$3*1000*E7/100,E7*$D$3/Inputs!$B$9) -> 6.3 | H7: ☐
A8: 3 | B8: Elatus Ace | C8: A | D8: Elatus Ace | E8: 500 | F8: ml/ha | G8: =IF(F8="% v/v",$D$3*1000*E8/100,E8*$D$3/Inputs!$B$9) -> 6.3 | H8: ☐
A9: 4 | B9: Opera | C9: A | D9: Opera | E9: 750 | F9: ml/ha | G9: =IF(F9="% v/v",$D$3*1000*E9/100,E9*$D$3/Inputs!$B$9) -> 9.45 | H9: ☐
A10: 5 | B10: Radial Opti (made up) | C10: A | D10: Amistar 250 SC | E10: 320 | F10: ml/ha | G10: =IF(F10="% v/v",$D$3*1000*E10/100,E10*$D$3/Inputs!$B$9) -> 4.032 | H10: ☐
D11: Soprano 500 | E11: 125 | F11: ml/ha | G11: =IF(F11="% v/v",$D$3*1000*E11/100,E11*$D$3/Inputs!$B$9) -> 1.575 | H11: ☐
D12: Hasten | E12: 0.5 | F12: % v/v | G12: =IF(F12="% v/v",$D$3*1000*E12/100,E12*$D$3/Inputs!$B$9) -> 6.3 | H12: ☐
A13: 6 | B13: Proviso Opti | C13: A | D13: Proline | E13: 240 | F13: ml/ha | G13: =IF(F13="% v/v",$D$3*1000*E13/100,E13*$D$3/Inputs!$B$9) -> 3.024 | H13: ☐
D14: BS1000 | E14: 0.25 | F14: % v/v | G14: =IF(F14="% v/v",$D$3*1000*E14/100,E14*$D$3/Inputs!$B$9) -> 3.15 | H14: ☐
A15: 7 | B15: Revystar | C15: A | D15: Revystar | E15: 750 | F15: ml/ha | G15: =IF(F15="% v/v",$D$3*1000*E15/100,E15*$D$3/Inputs!$B$9) -> 9.45 | H15: ☐
A16: 8 | B16: Balaya A+B | C16: A | D16: Balaya | E16: 750 | F16: ml/ha | G16: =IF(F16="% v/v",$D$3*1000*E16/100,E16*$D$3/Inputs!$B$9) -> 9.45 | H16: ☐
A17: 9 | B17: Flute A | C17: A | D17: Flute | E17: 150 | F17: ml/ha | G17: =IF(F17="% v/v",$D$3*1000*E17/100,E17*$D$3/Inputs!$B$9) -> 1.89 | H17: ☐
D18: Proviso Opti | E18: 240 | F18: ml/ha | G18: =IF(F18="% v/v",$D$3*1000*E18/100,E18*$D$3/Inputs!$B$9) -> 3.024 | H18: ☐
D19: BS1000 | E19: 0.25 | F19: % v/v | G19: =IF(F19="% v/v",$D$3*1000*E19/100,E19*$D$3/Inputs!$B$9) -> 3.15 | H19: ☐
A20: 10 | B20: Experimental 1 A | C20: A | D20: G295 (Adama) | E20: 150 | F20: ml/ha | G20: =IF(F20="% v/v",$D$3*1000*E20/100,E20*$D$3/Inputs!$B$9) -> 1.89 | H20: ☐
D21: Proviso Opti | E21: 240 | F21: ml/ha | G21: =IF(F21="% v/v",$D$3*1000*E21/100,E21*$D$3/Inputs!$B$9) -> 3.024 | H21: ☐
D22: BS1000 | E22: 0.25 | F22: % v/v | G22: =IF(F22="% v/v",$D$3*1000*E22/100,E22*$D$3/Inputs!$B$9) -> 3.15 | H22: ☐
A23: 11 | B23: Experimental 2 AL | C23: A | D23: Vimoy Iblon (Bayer) | E23: 300 | F23: ml/ha | G23: =IF(F23="% v/v",$D$3*1000*E23/100,E23*$D$3/Inputs!$B$9) -> 3.78 | H23: ☐
D24: Proviso Opti | E24: 240 | F24: ml/ha | G24: =IF(F24="% v/v",$D$3*1000*E24/100,E24*$D$3/Inputs!$B$9) -> 3.024 | H24: ☐
D25: BS1000 | E25: 0.25 | F25: % v/v | G25: =IF(F25="% v/v",$D$3*1000*E25/100,E25*$D$3/Inputs!$B$9) -> 3.15 | H25: ☐
A26: 12 | B26: Experimental 2 AH | C26: A | D26: Vimoy Iblon (Bayer) | E26: 500 | F26: ml/ha | G26: =IF(F26="% v/v",$D$3*1000*E26/100,E26*$D$3/Inputs!$B$9) -> 6.3 | H26: ☐
D27: Proviso Opti | E27: 240 | F27: ml/ha | G27: =IF(F27="% v/v",$D$3*1000*E27/100,E27*$D$3/Inputs!$B$9) -> 3.024 | H27: ☐
D28: BS1000 | E28: 0.25 | F28: % v/v | G28: =IF(F28="% v/v",$D$3*1000*E28/100,E28*$D$3/Inputs!$B$9) -> 3.15 | H28: ☐
A29: 13 | B29: Experimental 3 A | C29: A | D29: Elatus Flexi | E29: 500 | F29: ml/ha | G29: =IF(F29="% v/v",$D$3*1000*E29/100,E29*$D$3/Inputs!$B$9) -> 6.3 | H29: ☐
D30: Proviso Opti | E30: 240 | F30: ml/ha | G30: =IF(F30="% v/v",$D$3*1000*E30/100,E30*$D$3/Inputs!$B$9) -> 3.024 | H30: ☐
D31: BS1000 | E31: 0.25 | F31: % v/v | G31: =IF(F31="% v/v",$D$3*1000*E31/100,E31*$D$3/Inputs!$B$9) -> 3.15 | H31: ☐
A32: 14 | B32: Experimental 4 A | C32: A | D32: CUF37 (Syngenta) | E32: 750 | F32: ml/ha | G32: =IF(F32="% v/v",$D$3*1000*E32/100,E32*$D$3/Inputs!$B$9) -> 9.45 | H32: ☐
A33: 15 | B33: Balaya B | C33: A | D33: Soprano 500 | E33: 125 | F33: ml/ha | G33: =IF(F33="% v/v",$D$3*1000*E33/100,E33*$D$3/Inputs!$B$9) -> 1.575 | H33: ☐
A34: 16 | B34: Flute B | C34: A | D34: Soprano 500 | E34: 125 | F34: ml/ha | G34: =IF(F34="% v/v",$D$3*1000*E34/100,E34*$D$3/Inputs!$B$9) -> 1.575 | H34: ☐
A35: 17 | B35: Experimental 2 BL | C35: A | D35: Soprano 500 | E35: 125 | F35: ml/ha | G35: =IF(F35="% v/v",$D$3*1000*E35/100,E35*$D$3/Inputs!$B$9) -> 1.575 | H35: ☐
A36: 18 | B36: Experimental 2 BH | C36: A | D36: Soprano 500 | E36: 125 | F36: ml/ha | G36: =IF(F36="% v/v",$D$3*1000*E36/100,E36*$D$3/Inputs!$B$9) -> 1.575 | H36: ☐
A37: 19 | B37: Experimental 3 B | C37: A | D37: Soprano 500 | E37: 125 | F37: ml/ha | G37: =IF(F37="% v/v",$D$3*1000*E37/100,E37*$D$3/Inputs!$B$9) -> 1.575 | H37: ☐
A38: 20 | B38: Experimental 4 B | C38: A | D38: Soprano 500 | E38: 125 | F38: ml/ha | G38: =IF(F38="% v/v",$D$3*1000*E38/100,E38*$D$3/Inputs!$B$9) -> 1.575 | H38: ☐
A39: 21 | B39: Marvis A+B | C39: A | D39: Marvis Star | E39: 500 | F39: ml/ha | G39: =IF(F39="% v/v",$D$3*1000*E39/100,E39*$D$3/Inputs!$B$9) -> 6.3 | H39: ☐
A40: 22 | B40: Marvis A | C40: A | D40: Marvis Star | E40: 500 | F40: ml/ha | G40: =IF(F40="% v/v",$D$3*1000*E40/100,E40*$D$3/Inputs!$B$9) -> 6.3 | H40: ☐
A41: 23 | B41: Balaya A | C41: A | D41: Balaya | E41: 750 | F41: ml/ha | G41: =IF(F41="% v/v",$D$3*1000*E41/100,E41*$D$3/Inputs!$B$9) -> 9.45 | H41: ☐
...

Sheet Ringwood Wheat Plots
A1: AGnVET Services — IK Caldwell
A2: Ringwood Wheat Fungicide Trial — Plot Allocation
A3: 24 treatments, RCB, 3 reps · plot 2 m × 12 m, 100 L/ha · rep 1 = rows 1–4, rep 2 = rows 6–9, rep 3 = rows 9–12
A5: Trt | B5: Treatment | C5: Rep 1 | D5: Rep 2 | E5: Rep 3 | F5: Extra plot | G5: B spray? | H5: Notes
A6: 1 | B6: =INDEX('Wheat Mixing'!$B$6:$B$42,MATCH($A6,'Wheat Mixing'!$A$6:$A$42,0)) -> Untreated | C6: 101 | D6: 604 | E6: 906 | G6: No
A7: 2 | B7: =INDEX('Wheat Mixing'!$B$6:$B$42,MATCH($A7,'Wheat Mixing'!$A$6:$A$42,0)) -> Aviator Xpro | C7: 102 | D7: 902 | E7: 1002 | G7: Yes
A8: 3 | B8: =INDEX('Wheat Mixing'!$B$6:$B$42,MATCH($A8,'Wheat Mixing'!$A$6:$A$42,0)) -> Elatus Ace | C8: 103 | D8: 808 | E8: 1108 | G8: Yes
A9: 4 | B9: =INDEX('Wheat Mixing'!$B$6:$B$42,MATCH($A9,'Wheat Mixing'!$A$6:$A$42,0)) -> Opera | C9: 104 | D9: 601 | E9: 1103 | G9: Yes
A10: 5 | B10: =INDEX('Wheat Mixing'!$B$6:$B$42,MATCH($A10,'Wheat Mixing'!$A$6:$A$42,0)) -> Radial Opti (made up) | C10: 105 | D10: 606 | E10: 1207 | G10: Yes | H10: plot 105 marginal — flag at assessment
A11: 6 | B11: =INDEX('Wheat Mixing'!$B$6:$B$42,MATCH($A11,'Wheat Mixing'!$A$6:$A$42,0)) -> Proviso Opti | C11: 106 | D11: 701 | E11: 1204 | G11: Yes
A12: 7 | B12: =INDEX('Wheat Mixing'!$B$6:$B$42,MATCH($A12,'Wheat Mixing'!$A$6:$A$42,0)) -> Revystar | C12: 107 | D12: 605 | E12: 1006 | G12: Yes
A13: 8 | B13: =INDEX('Wheat Mixing'!$B$6:$B$42,MATCH($A13,'Wheat Mixing'!$A$6:$A$42,0)) -> Balaya A+B | C13: 108 | D13: 802 | E13: 1007 | G13: Yes | H13: plot 108 marginal — flag at assessment
A14: 9 | B14: =INDEX('Wheat Mixing'!$B$6:$B$42,MATCH($A14,'Wheat Mixing'!$A$6:$A$42,0)) -> Flute A | C14: 202 | D14: 603 | E14: 1003 | G14: Yes
A15: 10 | B15: =INDEX('Wheat Mixing'!$B$6:$B$42,MATCH($A15,'Wheat Mixing'!$A$6:$A$42,0)) -> Experimental 1 A | C15: 203 | D15: 807 | E15: 1105 | G15: Yes
A16: 11 | B16: =INDEX('Wheat Mixing'!$B$6:$B$42,MATCH($A16,'Wheat Mixing'!$A$6:$A$42,0)) -> Experimental 2 AL | C16: 206 | D16: 704 | E16: 903 | G16: Yes | H16: plot 704 marginal — flag at assessment
A17: 12 | B17: =INDEX('Wheat Mixing'!$B$6:$B$42,MATCH($A17,'Wheat Mixing'!$A$6:$A$42,0)) -> Experimental 2 AH | C17: 207 | D17: 705 | E17: 1008 | G17: Yes
A18: 13 | B18: =INDEX('Wheat Mixing'!$B$6:$B$42,MATCH($A18,'Wheat Mixing'!$A$6:$A$42,0)) -> Experimental 3 A | C18: 301 | D18: 602 | E18: 1004 | G18: Yes
A19: 14 | B19: =INDEX('Wheat Mixing'!$B$6:$B$42,MATCH($A19,'Wheat Mixing'!$A$6:$A$42,0)) -> Experimental 4 A | C19: 302 | D19: 804 | E19: 904 | G19: Yes
A20: 15 | B20: =INDEX('Wheat Mixing'!$B$6:$B$42,MATCH($A20,'Wheat Mixing'!$A$6:$A$42,0)) -> Balaya B | C20: 303 | D20: 703 | E20: 1206 | G20: Yes
A21: 16 | B21: =INDEX('Wheat Mixing'!$B$6:$B$42,MATCH($A21,'Wheat Mixing'!$A$6:$A$42,0)) -> Flute B | C21: 304 | D21: 607 | E21: 1107 | G21: Yes
A22: 17 | B22: =INDEX('Wheat Mixing'!$B$6:$B$42,MATCH($A22,'Wheat Mixing'!$A$6:$A$42,0)) -> Experimental 2 BL | C22: 305 | D22: 707 | E22: 1005 | G22: Yes
A23: 18 | B23: =INDEX('Wheat Mixing'!$B$6:$B$42,MATCH($A23,'Wheat Mixing'!$A$6:$A$42,0)) -> Experimental 2 BH | C23: 306 | D23: 702 | E23: 1205 | G23: Yes
A24: 19 | B24: =INDEX('Wheat Mixing'!$B$6:$B$42,MATCH($A24,'Wheat Mixing'!$A$6:$A$42,0)) -> Experimental 3 B | C24: 307 | D24: 608 | E24: 907 | G24: Yes
A25: 20 | B25: =INDEX('Wheat Mixing'!$B$6:$B$42,MATCH($A25,'Wheat Mixing'!$A$6:$A$42,0)) -> Experimental 4 B | C25: 308 | D25: 805 | E25: 1102 | G25: Yes
A26: 21 | B26: =INDEX('Wheat Mixing'!$B$6:$B$42,MATCH($A26,'Wheat Mixing'!$A$6:$A$42,0)) -> Marvis A+B | C26: 403 | D26: 806 | E26: 1202 | G26: Yes
A27: 22 | B27: =INDEX('Wheat Mixing'!$B$6:$B$42,MATCH($A27,'Wheat Mixing'!$A$6:$A$42,0)) -> Marvis A | C27: 406 | D27: 803 | E27: 1203 | G27: No
A28: 23 | B28: =INDEX('Wheat Mixing'!$B$6:$B$42,MATCH($A28,'Wheat Mixing'!$A$6:$A$42,0)) -> Balaya A | C28: 407 | D28: 706 | E28: 1208 | G28: No
A29: 24 | B29: =INDEX('Wheat Mixing'!$B$6:$B$42,MATCH($A29,'Wheat Mixing'!$A$6:$A$42,0)) -> Opus A | C29: 408 | D29: 708 | E29: 905 | G29: No | H29: plot 708 marginal — flag at assessment
A31: Plots sprayed at A (count of all plot IDs above): | D31: =COUNT(C6:F29) -> 72
A33: Write-offs, not used: 205, 901, 1001, 1101, 1201.
A34: Marginal and not used: 201, 204, 208, 401, 402, 404, 405, 501–508 (all of row 5), 801, 908, 1104, 1106.
A35: Marginal but carrying a treatment: 105, 108, 704, 708 — the third rep needs 72 plots and only 68 are clean.
A36: Trt 24 is 'Opus A' on the Wheat Mixing tab and 'Soprano A' on the spray map — same treatment (Soprano 500 at 125 ml/ha).
A37: Flutriafol breakdown block sits immediately beside row 1 — do not spray into it.

Sheet Ringwood App Record
A1: AGnVET Services — IK Caldwell
A2: Ringwood — Fungicide Trial Application Record
A3: 2026 season · Wheat (24 trt, 3 reps)
A5: APPLICATION A
A6: Date
A7: Site | B7: Ringwood (Corowa)
A8: Operator | B8: Andrew Rolfe
A9: Assistance
A10: Sprayer / water rate | B10: =Inputs!B9&" "&Inputs!C9 -> 100 L/ha
A12: Crop | B12: Timing | C12: Start | D12: Finish | E12: Temp (°C) | F12: Wind (km/h) | G12: Wind dir. | H12: Water (L/ha) | I12: Plots sprayed | J12: Notes
A13: Wheat | B13: A | H13: =Inputs!$B$9 -> 100 | I13: ='Ringwood Wheat Plots'!$D$31 -> 72
A14: Wheat | B14: B | H14: =Inputs!$B$9 -> 100
A16: PLOT CHANGES — deviations from the spray map
A17: Plot | B17: Trt sprayed | C17: Treatment | D17: Rep | E17: Per spray map | F17: Comment
C18: =IF($B18="","",INDEX('Wheat Mixing'!$B$6:$B$42,MATCH($B18,'Wheat Mixing'!$A$6:$A$42,0)))
C19: =IF($B19="","",INDEX('Wheat Mixing'!$B$6:$B$42,MATCH($B19,'Wheat Mixing'!$A$6:$A$42,0)))
C20: =IF($B20="","",INDEX('Wheat Mixing'!$B$6:$B$42,MATCH($B20,'Wheat Mixing'!$A$6:$A$42,0)))
C21: =IF($B21="","",INDEX('Wheat Mixing'!$B$6:$B$42,MATCH($B21,'Wheat Mixing'!$A$6:$A$42,0)))
A23: Record any plot sprayed differently to the map here, on the day.
A25: SIGN-OFF
A26: Role | B26: Name | C26: Signature | D26: Date
A27: Applicator | B27: Andrew Rolfe
A28: Assistance
A29: Assistance
A30: Assistance
A32: Application B — wheat trts 2–21 only (1, 22, 23, 24 are A only).
